Workbook

Sheet Parameters
A1: H237 Manual Rebalancing Parameters — Full History
A3: Parameter | B3: Value | C3: Units | D3: Meaning
A4: Upside-beta lookback | B4: 26 | C4: weeks | D4: Use the latest 26 completed weekly A/B return observations, including the current completed week.
A5: Persistence requirement | B5: 3 | C5: consecutive signals | D5: H237 acts only when the same raw H135 direction has appeared for at least 3 consecutive completed weeks.
A6: Weekly allocation move | B6: 0.1 | C6: percentage points | D6: Each confirmed H237 signal moves A weight by 10 percentage points from the current post-trade/pre-rebalance weight.
A7: Minimum A weight | B7: 0 | C7: % | D7: Full-range allocator may reach 0% A / 100% B.
A8: Maximum A weight | B8: 1 | C8: % | D8: Full-range allocator may reach 100% A / 0% B.
A9: Historical actual initial A | B9: 50000 | C9: account units | D9: Normalized historical decision path starts with 50,000 in A.
A10: Historical actual initial B | B10: 50000 | C10: account units | D10: Normalized historical decision path starts with 50,000 in B.
A11: Tax rate | B11: 0.19 | C11: % | D11: 19% of positive sleeve-specific realized P/L accrual at source-observed tax-event weeks.
A12: Margin quantum | B12: 115 | C12: account units | D12: Margin is floored to 115-unit increments.
A13: Gross exposure per margin | B13: 20 | C13: x | D13: P/L = margin × 20 × raw weekly return.
A14: Target leverage | B14: 13.333333 | C14: x | D14: Exact 13⅓× target leverage.
A15: Historical weekly top-up | B15: 0 | C15: account units | D15: No top-ups in this normalized historical reconstruction.
A16: Future manual rows | B16: 104 | C16: weeks | D16: Blank decision rows after 2026-08-03 for manual weekly use.
A19: Latest Historical H237 State / Backtest Check
A20: Latest completed week | B20: ='H237 Tracker'!A437 -> 46237 | C20: date | D20: Latest source week.
A21: Upside Beta A | B21: ='H237 Tracker'!F437 -> 0.9589331 | C21: beta | D21: Positive-common-factor beta over the latest 26 weeks.
A22: Upside Beta B | B22: ='H237 Tracker'!G437 -> 1.0410669 | C22: beta | D22: Positive-common-factor beta over the latest 26 weeks.
A23: Beta gap (A−B) | B23: ='H237 Tracker'!H437 -> -0.082133808 | C23: beta | D23: Positive favors A; negative favors B.
A24: Raw H135 signal | B24: ='H237 Tracker'!I437 -> B | C24: signal | D24: Raw H135 direction before persistence filter.
A25: Raw signal streak | B25: ='H237 Tracker'!J437 -> 1 | C25: weeks | D25: Consecutive same-direction raw signals.
A26: H237 confirmed signal | B26: ='H237 Tracker'!K437 -> HOLD | C26: signal | D26: Only A/B once streak reaches 3; otherwise HOLD.
A27: Current A weight before rebalance | B27: ='H237 Tracker'!N437 -> 0 | C27: % | D27: Actual post-trade/pre-rebalance A share.
A28: Recommended A weight | B28: ='H237 Tracker'!O437 -> 0 | C28: % | D28: 10pp move if confirmed; HOLD preserves natural drift.
A29: Recommended action | B29: ='H237 Tracker'!U437 -> No transfer | C29: text | D29: Manual transfer instruction for the historical path.
A30: Historical ending portfolio | B30: ='Actual Calc'!AE437 -> 9.7571538e+13 | C30: account units | D30: Historical 100k/no-top-up/tax-on reconstruction.
A31: Full-history weekly geo | B31: =('Actual Calc'!AE437/(B9+B10))^(1/434)-1 -> 0.048848415 | C31: % / week | D31: Uses 434 completed weekly observations.
A32: Full-history annualized CAGR | B32: =(1+B31)^52-1 -> 10.941579 | C32: % / year | D32: Mathematical annualization of weekly geometric growth.
A33: Full-history max drawdown | B33: =-MIN('Actual Calc'!AG4:AG437) -> 0.67289754 | C33: % | D33: Historical peak-to-trough drawdown of the reconstructed H237 portfolio.
A34: Ending A after rebalance | B34: ='Actual Calc'!AC437 -> 0 | C34: account units | D34: Historical normalized sleeve after the final 2026-08-03 rebalance.
A35: Ending B after rebalance | B35: ='Actual Calc'!AD437 -> 9.7571538e+13 | C35: account units | D35: Historical normalized sleeve after the final 2026-08-03 rebalance.

Sheet H237 Tracker
A1: H237 Weekly Manual Rebalancing Tracker — Full History
A2: Historical source: Wklejony tekst(20260814-114014).txt | A = plain --leverage_override; B = --gap-momentum --tuesday-normalization --premarket-low --or5-exit | 2018-04-16 to 2026-08-03. Missing strategy weeks are stored as 0.00%. Historical actual path: 100,000 total, no top-ups, taxes ON.
A3: Week Start | B3: A Raw Return % | C3: B Raw Return % | D3: Common Factor % | E3: Positive Weeks (26w) | F3: Upside Beta A | G3: Upside Beta B | H3: Beta Gap (A−B) | I3: Raw H135 Signal | J3: Raw Signal Streak | K3: H237 Signal | L3: Actual A Before Rebalance | M3: Actual B Before Rebalance | N3: Current A Weight | O3: Recommended A Weight | P3: Transfer A→B | Q3: Transfer B→A | R3: Recommended A After | S3: Recommended B After | T3: Recommended A Weight | U3: Action | V3: Notes
A4: 43206 | B4: 0.02172 | C4: 0.02172 | D4: =IF(AND(ISNUMBER(B4),ISNUMBER(C4)),(B4+C4)/2,"") -> 0.02172 | E4: ="" | F4: ="" | G4: ="" | H4: =IF(AND(ISNUMBER(F4),ISNUMBER(G4)),F4-G4,"") | I4: =IF(OR(NOT(ISNUMBER(F4)),NOT(ISNUMBER(G4))),"",IF(F4>G4,"A",IF(G4>F4,"B","HOLD"))) | J4: =IF(I4="","",IF(I4="HOLD",0,1)) | K4: =IF(I4="","",IF(J4>=Parameters!$B$5,I4,"HOLD")) | L4: ='Actual Calc'!T4 -> 64437.284 | M4: ='Actual Calc'!U4 -> 64437.284 | N4: =IF(OR(NOT(ISNUMBER(L4)),NOT(ISNUMBER(M4)),L4+M4=0),"",L4/(L4+M4)) -> 0.5 | O4: =IF(NOT(ISNUMBER(N4)),"",IF(K4="A",MIN(Parameters!$B$8,N4+Parameters!$B$6),IF(K4="B",MAX(Parameters!$B$7,N4-Parameters!$B$6),N4))) -> 0.5 | P4: =IF(NOT(ISNUMBER(O4)),"",MAX(0,L4-(L4+M4)*O4)) -> 0 | Q4: =IF(NOT(ISNUMBER(O4)),"",MAX(0,(L4+M4)*O4-L4)) -> 0 | R4: =IF(NOT(ISNUMBER(O4)),"",L4-P4+Q4) -> 64437.284 | S4: =IF(NOT(ISNUMBER(O4)),"",M4+P4-Q4) -> 64437.284 | T4: =IF(OR(NOT(ISNUMBER(R4)),NOT(ISNUMBER(S4)),R4+S4=0),"",R4/(R4+S4)) -> 0.5 | U4: =IF(NOT(ISNUMBER(O4)),"",IF(P4>0.005,"Transfer "&TEXT(P4,"#,##0.00")&" A → B",IF(Q4>0.005,"Transfer "&TEXT(Q4,"#,##0.00")&" B → A","No transfer"))) -> No transfer | V4: Historical
A5: 43213 | B5: -0.01701 | C5: -0.01701 | D5: =IF(AND(ISNUMBER(B5),ISNUMBER(C5)),(B5+C5)/2,"") -> -0.01701 | E5: ="" | F5: ="" | G5: ="" | H5: =IF(AND(ISNUMBER(F5),ISNUMBER(G5)),F5-G5,"") | I5: =IF(OR(NOT(ISNUMBER(F5)),NOT(ISNUMBER(G5))),"",IF(F5>G5,"A",IF(G5>F5,"B","HOLD"))) | J5: =IF(I5="","",IF(I5="HOLD",0,IF(I5=I4,J4+1,1))) | K5: =IF(I5="","",IF(J5>=Parameters!$B$5,I5,"HOLD")) | L5: ='Actual Calc'!T5 -> 49844.405 | M5: ='Actual Calc'!U5 -> 49844.405 | N5: =IF(OR(NOT(ISNUMBER(L5)),NOT(ISNUMBER(M5)),L5+M5=0),"",L5/(L5+M5)) -> 0.5 | O5: =IF(NOT(ISNUMBER(N5)),"",IF(K5="A",MIN(Parameters!$B$8,N5+Parameters!$B$6),IF(K5="B",MAX(Parameters!$B$7,N5-Parameters!$B$6),N5))) -> 0.5 | P5: =IF(NOT(ISNUMBER(O5)),"",MAX(0,L5-(L5+M5)*O5)) -> 0 | Q5: =IF(NOT(ISNUMBER(O5)),"",MAX(0,(L5+M5)*O5-L5)) -> 0 | R5: =IF(NOT(ISNUMBER(O5)),"",L5-P5+Q5) -> 49844.405 | S5: =IF(NOT(ISNUMBER(O5)),"",M5+P5-Q5) -> 49844.405 | T5: =IF(OR(NOT(ISNUMBER(R5)),NOT(ISNUMBER(S5)),R5+S5=0),"",R5/(R5+S5)) -> 0.5 | U5: =IF(NOT(ISNUMBER(O5)),"",IF(P5>0.005,"Transfer "&TEXT(P5,"#,##0.00")&" A → B",IF(Q5>0.005,"Transfer "&TEXT(Q5,"#,##0.00")&" B → A","No transfer"))) -> No transfer | V5: Historical
A6: 43220 | B6: -0.00607 | C6: -0.00607 | D6: =IF(AND(ISNUMBER(B6),ISNUMBER(C6)),(B6+C6)/2,"") -> -0.00607 | E6: ="" | F6: ="" | G6: ="" | H6: =IF(AND(ISNUMBER(F6),ISNUMBER(G6)),F6-G6,"") | I6: =IF(OR(NOT(ISNUMBER(F6)),NOT(ISNUMBER(G6))),"",IF(F6>G6,"A",IF(G6>F6,"B","HOLD"))) | J6: =IF(I6="","",IF(I6="HOLD",0,IF(I6=I5,J5+1,1))) | K6: =IF(I6="","",IF(J6>=Parameters!$B$5,I6,"HOLD")) | L6: ='Actual Calc'!T6 -> 45823.637 | M6: ='Actual Calc'!U6 -> 45823.637 | N6: =IF(OR(NOT(ISNUMBER(L6)),NOT(ISNUMBER(M6)),L6+M6=0),"",L6/(L6+M6)) -> 0.5 | O6: =IF(NOT(ISNUMBER(N6)),"",IF(K6="A",MIN(Parameters!$B$8,N6+Parameters!$B$6),IF(K6="B",MAX(Parameters!$B$7,N6-Parameters!$B$6),N6))) -> 0.5 | P6: =IF(NOT(ISNUMBER(O6)),"",MAX(0,L6-(L6+M6)*O6)) -> 0 | Q6: =IF(NOT(ISNUMBER(O6)),"",MAX(0,(L6+M6)*O6-L6)) -> 0 | R6: =IF(NOT(ISNUMBER(O6)),"",L6-P6+Q6) -> 45823.637 | S6: =IF(NOT(ISNUMBER(O6)),"",M6+P6-Q6) -> 45823.637 | T6: =IF(OR(NOT(ISNUMBER(R6)),NOT(ISNUMBER(S6)),R6+S6=0),"",R6/(R6+S6)) -> 0.5 | U6: =IF(NOT(ISNUMBER(O6)),"",IF(P6>0.005,"Transfer "&TEXT(P6,"#,##0.00")&" A → B",IF(Q6>0.005,"Transfer "&TEXT(Q6,"#,##0.00")&" B → A","No transfer"))) -> No transfer | V6: Historical
A7: 43227 | B7: 0.02286 | C7: 0.02286 | D7: =IF(AND(ISNUMBER(B7),ISNUMBER(C7)),(B7+C7)/2,"") -> 0.02286 | E7: ="" | F7: ="" | G7: ="" | H7: =IF(AND(ISNUMBER(F7),ISNUMBER(G7)),F7-G7,"") | I7: =IF(OR(NOT(ISNUMBER(F7)),NOT(ISNUMBER(G7))),"",IF(F7>G7,"A",IF(G7>F7,"B","HOLD"))) | J7: =IF(I7="","",IF(I7="HOLD",0,IF(I7=I6,J6+1,1))) | K7: =IF(I7="","",IF(J7>=Parameters!$B$5,I7,"HOLD")) | L7: ='Actual Calc'!T7 -> 59756.807 | M7: ='Actual Calc'!U7 -> 59756.807 | N7: =IF(OR(NOT(ISNUMBER(L7)),NOT(ISNUMBER(M7)),L7+M7=0),"",L7/(L7+M7)) -> 0.5 | O7: =IF(NOT(ISNUMBER(N7)),"",IF(K7="A",MIN(Parameters!$B$8,N7+Parameters!$B$6),IF(K7="B",MAX(Parameters!$B$7,N7-Parameters!$B$6),N7))) -> 0.5 | P7: =IF(NOT(ISNUMBER(O7)),"",MAX(0,L7-(L7+M7)*O7)) -> 0 | Q7: =IF(NOT(ISNUMBER(O7)),"",MAX(0,(L7+M7)*O7-L7)) -> 0 | R7: =IF(NOT(ISNUMBER(O7)),"",L7-P7+Q7) -> 59756.807 | S7: =IF(NOT(ISNUMBER(O7)),"",M7+P7-Q7) -> 59756.807 | T7: =IF(OR(NOT(ISNUMBER(R7)),NOT(ISNUMBER(S7)),R7+S7=0),"",R7/(R7+S7)) -> 0.5 | U7: =IF(NOT(ISNUMBER(O7)),"",IF(P7>0.005,"Transfer "&TEXT(P7,"#,##0.00")&" A → B",IF(Q7>0.005,"Transfer "&TEXT(Q7,"#,##0.00")&" B → A","No transfer"))) -> No transfer | V7: Historical
A8: 43234 | B8: -0.004 | C8: -0.004 | D8: =IF(AND(ISNUMBER(B8),ISNUMBER(C8)),(B8+C8)/2,"") -> -0.004 | E8: ="" | F8: ="" | G8: ="" | H8: =IF(AND(ISNUMBER(F8),ISNUMBER(G8)),F8-G8,"") | I8: =IF(OR(NOT(ISNUMBER(F8)),NOT(ISNUMBER(G8))),"",IF(F8>G8,"A",IF(G8>F8,"B","HOLD"))) | J8: =IF(I8="","",IF(I8="HOLD",0,IF(I8=I7,J7+1,1))) | K8: =IF(I8="","",IF(J8>=Parameters!$B$5,I8,"HOLD")) | L8: ='Actual Calc'!T8 -> 56573.607 | M8: ='Actual Calc'!U8 -> 56573.607 | N8: =IF(OR(NOT(ISNUMBER(L8)),NOT(ISNUMBER(M8)),L8+M8=0),"",L8/(L8+M8)) -> 0.5 | O8: =IF(NOT(ISNUMBER(N8)),"",IF(K8="A",MIN(Parameters!$B$8,N8+Parameters!$B$6),IF(K8="B",MAX(Parameters!$B$7,N8-Parameters!$B$6),N8))) -> 0.5 | P8: =IF(NOT(ISNUMBER(O8)),"",MAX(0,L8-(L8+M8)*O8)) -> 0 | Q8: =IF(NOT(ISNUMBER(O8)),"",MAX(0,(L8+M8)*O8-L8)) -> 0 | R8: =IF(NOT(ISNUMBER(O8)),"",L8-P8+Q8) -> 56573.607 | S8: =IF(NOT(ISNUMBER(O8)),"",M8+P8-Q8) -> 56573.607 | T8: =IF(OR(NOT(ISNUMBER(R8)),NOT(ISNUMBER(S8)),R8+S8=0),"",R8/(R8+S8)) -> 0.5 | U8: =IF(NOT(ISNUMBER(O8)),"",IF(P8>0.005,"Transfer "&TEXT(P8,"#,##0.00")&" A → B",IF(Q8>0.005,"Transfer "&TEXT(Q8,"#,##0.00")&" B → A","No transfer"))) -> No transfer | V8: Historical
A9: 43241 | B9: -0.004 | C9: -0.004 | D9: =IF(AND(ISNUMBER(B9),ISNUMBER(C9)),(B9+C9)/2,"") -> -0.004 | E9: ="" | F9: ="" | G9: ="" | H9: =IF(AND(ISNUMBER(F9),ISNUMBER(G9)),F9-G9,"") | I9: =IF(OR(NOT(ISNUMBER(F9)),NOT(ISNUMBER(G9))),"",IF(F9>G9,"A",IF(G9>F9,"B","HOLD"))) | J9: =IF(I9="","",IF(I9="HOLD",0,IF(I9=I8,J8+1,1))) | K9: =IF(I9="","",IF(J9>=Parameters!$B$5,I9,"HOLD")) | L9: ='Actual Calc'!T9 -> 53565.207 | M9: ='Actual Calc'!U9 -> 53565.207 | N9: =IF(OR(NOT(ISNUMBER(L9)),NOT(ISNUMBER(M9)),L9+M9=0),"",L9/(L9+M9)) -> 0.5 | O9: =IF(NOT(ISNUMBER(N9)),"",IF(K9="A",MIN(Parameters!$B$8,N9+Parameters!$B$6),IF(K9="B",MAX(Parameters!$B$7,N9-Parameters!$B$6),N9))) -> 0.5 | P9: =IF(NOT(ISNUMBER(O9)),"",MAX(0,L9-(L9+M9)*O9)) -> 0 | Q9: =IF(NOT(ISNUMBER(O9)),"",MAX(0,(L9+M9)*O9-L9)) -> 0 | R9: =IF(NOT(ISNUMBER(O9)),"",L9-P9+Q9) -> 53565.207 | S9: =IF(NOT(ISNUMBER(O9)),"",M9+P9-Q9) -> 53565.207 | T9: =IF(OR(NOT(ISNUMBER(R9)),NOT(ISNUMBER(S9)),R9+S9=0),"",R9/(R9+S9)) -> 0.5 | U9: =IF(NOT(ISNUMBER(O9)),"",IF(P9>0.005,"Transfer "&TEXT(P9,"#,##0.00")&" A → B",IF(Q9>0.005,"Transfer "&TEXT(Q9,"#,##0.00")&" B → A","No transfer"))) -> No transfer | V9: Historical
A10: 43248 | B10: 0.02264 | C10: 0.02264 | D10: =IF(AND(ISNUMBER(B10),ISNUMBER(C10)),(B10+C10)/2,"") -> 0.02264 | E10: ="" | F10: ="" | G10: ="" | H10: =IF(AND(ISNUMBER(F10),ISNUMBER(G10)),F10-G10,"") | I10: =IF(OR(NOT(ISNUMBER(F10)),NOT(ISNUMBER(G10))),"",IF(F10>G10,"A",IF(G10>F10,"B","HOLD"))) | J10: =IF(I10="","",IF(I10="HOLD",0,IF(I10=I9,J9+1,1))) | K10: =IF(I10="","",IF(J10>=Parameters!$B$5,I10,"HOLD")) | L10: ='Actual Calc'!T10 -> 69707.527 | M10: ='Actual Calc'!U10 -> 69707.527 | N10: =IF(OR(NOT(ISNUMBER(L10)),NOT(ISNUMBER(M10)),L10+M10=0),"",L10/(L10+M10)) -> 0.5 | O10: =IF(NOT(ISNUMBER(N10)),"",IF(K10="A",MIN(Parameters!$B$8,N10+Parameters!$B$6),IF(K10="B",MAX(Parameters!$B$7,N10-Parameters!$B$6),N10))) -> 0.5 | P10: =IF(NOT(ISNUMBER(O10)),"",MAX(0,L10-(L10+M10)*O10)) -> 0 | Q10: =IF(NOT(ISNUMBER(O10)),"",MAX(0,(L10+M10)*O10-L10)) -> 0 | R10: =IF(NOT(ISNUMBER(O10)),"",L10-P10+Q10) -> 69707.527 | S10: =IF(NOT(ISNUMBER(O10)),"",M10+P10-Q10) -> 69707.527 | T10: =IF(OR(NOT(ISNUMBER(R10)),NOT(ISNUMBER(S10)),R10+S10=0),"",R10/(R10+S10)) -> 0.5 | U10: =IF(NOT(ISNUMBER(O10)),"",IF(P10>0.005,"Transfer "&TEXT(P10,"#,##0.00")&" A → B",IF(Q10>0.005,"Transfer "&TEXT(Q10,"#,##0.00")&" B → A","No transfer"))) -> No transfer | V10: Historical
A11: 43255 | B11: 0.00749 | C11: 0.00749 | D11: =IF(AND(ISNUMBER(B11),ISNUMBER(C11)),(B11+C11)/2,"") -> 0.00749 | E11: ="" | F11: ="" | G11: ="" | H11: =IF(AND(ISNUMBER(F11),ISNUMBER(G11)),F11-G11,"") | I11: =IF(OR(NOT(ISNUMBER(F11)),NOT(ISNUMBER(G11))),"",IF(F11>G11,"A",IF(G11>F11,"B","HOLD"))) | J11: =IF(I11="","",IF(I11="HOLD",0,IF(I11=I10,J10+1,1))) | K11: =IF(I11="","",IF(J11>=Parameters!$B$5,I11,"HOLD")) | L11: ='Actual Calc'!T11 -> 76667.235 | M11: ='Actual Calc'!U11 -> 76667.235 | N11: =IF(OR(NOT(ISNUMBER(L11)),NOT(ISNUMBER(M11)),L11+M11=0),"",L11/(L11+M11)) -> 0.5 | O11: =IF(NOT(ISNUMBER(N11)),"",IF(K11="A",MIN(Parameters!$B$8,N11+Parameters!$B$6),IF(K11="B",MAX(Parameters!$B$7,N11-Parameters!$B$6),N11))) -> 0.5 | P11: =IF(NOT(ISNUMBER(O11)),"",MAX(0,L11-(L11+M11)*O11)) -> 0 | Q11: =IF(NOT(ISNUMBER(O11)),"",MAX(0,(L11+M11)*O11-L11)) -> 0 | R11: =IF(NOT(ISNUMBER(O11)),"",L11-P11+Q11) -> 76667.235 | S11: =IF(NOT(ISNUMBER(O11)),"",M11+P11-Q11) -> 76667.235 | T11: =IF(OR(NOT(ISNUMBER(R11)),NOT(ISNUMBER(S11)),R11+S11=0),"",R11/(R11+S11)) -> 0.5 | U11: =IF(NOT(ISNUMBER(O11)),"",IF(P11>0.005,"Transfer "&TEXT(P11,"#,##0.00")&" A → B",IF(Q11>0.005,"Transfer "&TEXT(Q11,"#,##0.00")&" B → A","No transfer"))) -> No transfer | V11: Historical
A12: 43262 | B12: 0.0156 | C12: 0.0156 | D12: =IF(AND(ISNUMBER(B12),ISNUMBER(C12)),(B12+C12)/2,"") -> 0.0156 | E12: ="" | F12: ="" | G12: ="" | H12: =IF(AND(ISNUMBER(F12),ISNUMBER(G12)),F12-G12,"") | I12: =IF(OR(NOT(ISNUMBER(F12)),NOT(ISNUMBER(G12))),"",IF(F12>G12,"A",IF(G12>F12,"B","HOLD"))) | J12: =IF(I12="","",IF(I12="HOLD",0,IF(I12=I11,J11+1,1))) | K12: =IF(I12="","",IF(J12>=Parameters!$B$5,I12,"HOLD")) | L12: ='Actual Calc'!T12 -> 92597.955 | M12: ='Actual Calc'!U12 -> 92597.955 | N12: =IF(OR(NOT(ISNUMBER(L12)),NOT(ISNUMBER(M12)),L12+M12=0),"",L12/(L12+M12)) -> 0.5 | O12: =IF(NOT(ISNUMBER(N12)),"",IF(K12="A",MIN(Parameters!$B$8,N12+Parameters!$B$6),IF(K12="B",MAX(Parameters!$B$7,N12-Parameters!$B$6),N12))) -> 0.5 | P12: =IF(NOT(ISNUMBER(O12)),"",MAX(0,L12-(L12+M12)*O12)) -> 0 | Q12: =IF(NOT(ISNUMBER(O12)),"",MAX(0,(L12+M12)*O12-L12)) -> 0 | R12: =IF(NOT(ISNUMBER(O12)),"",L12-P12+Q12) -> 92597.955 | S12: =IF(NOT(ISNUMBER(O12)),"",M12+P12-Q12) -> 92597.955 | T12: =IF(OR(NOT(ISNUMBER(R12)),NOT(ISNUMBER(S12)),R12+S12=0),"",R12/(R12+S12)) -> 0.5 | U12: =IF(NOT(ISNUMBER(O12)),"",IF(P12>0.005,"Transfer "&TEXT(P12,"#,##0.00")&" A → B",IF(Q12>0.005,"Transfer "&TEXT(Q12,"#,##0.00")&" B → A","No transfer"))) -> No transfer | V12: Historical
A13: 43269 | B13: -0.004 | C13: -0.004 | D13: =IF(AND(ISNUMBER(B13),ISNUMBER(C13)),(B13+C13)/2,"") -> -0.004 | E13: ="" | F13: ="" | G13: ="" | H13: =IF(AND(ISNUMBER(F13),ISNUMBER(G13)),F13-G13,"") | I13: =IF(OR(NOT(ISNUMBER(F13)),NOT(ISNUMBER(G13))),"",IF(F13>G13,"A",IF(G13>F13,"B","HOLD"))) | J13: =IF(I13="","",IF(I13="HOLD",0,IF(I13=I12,J12+1,1))) | K13: =IF(I13="","",IF(J13>=Parameters!$B$5,I13,"HOLD")) | L13: ='Actual Calc'!T13 -> 87666.755 | M13: ='Actual Calc'!U13 -> 87666.755 | N13: =IF(OR(NOT(ISNUMBER(L13)),NOT(ISNUMBER(M13)),L13+M13=0),"",L13/(L13+M13)) -> 0.5 | O13: =IF(NOT(ISNUMBER(N13)),"",IF(K13="A",MIN(Parameters!$B$8,N13+Parameters!$B$6),IF(K13="B",MAX(Parameters!$B$7,N13-Parameters!$B$6),N13))) -> 0.5 | P13: =IF(NOT(ISNUMBER(O13)),"",MAX(0,L13-(L13+M13)*O13)) -> 0 | Q13: =IF(NOT(ISNUMBER(O13)),"",MAX(0,(L13+M13)*O13-L13)) -> 0 | R13: =IF(NOT(ISNUMBER(O13)),"",L13-P13+Q13) -> 87666.755 | S13: =IF(NOT(ISNUMBER(O13)),"",M13+P13-Q13) -> 87666.755 | T13: =IF(OR(NOT(ISNUMBER(R13)),NOT(ISNUMBER(S13)),R13+S13=0),"",R13/(R13+S13)) -> 0.5 | U13: =IF(NOT(ISNUMBER(O13)),"",IF(P13>0.005,"Transfer "&TEXT(P13,"#,##0.00")&" A → B",IF(Q13>0.005,"Transfer "&TEXT(Q13,"#,##0.00")&" B → A","No transfer"))) -> No transfer | V13: Historical
A14: 43276 | B14: -0.004 | C14: -0.004 | D14: =IF(AND(ISNUMBER(B14),ISNUMBER(C14)),(B14+C14)/2,"") -> -0.004 | E14: ="" | F14: ="" | G14: ="" | H14: =IF(AND(ISNUMBER(F14),ISNUMBER(G14)),F14-G14,"") | I14: =IF(OR(NOT(ISNUMBER(F14)),NOT(ISNUMBER(G14))),"",IF(F14>G14,"A",IF(G14>F14,"B","HOLD"))) | J14: =IF(I14="","",IF(I14="HOLD",0,IF(I14=I13,J13+1,1))) | K14: =IF(I14="","",IF(J14>=Parameters!$B$5,I14,"HOLD")) | L14: ='Actual Calc'!T14 -> 82993.155 | M14: ='Actual Calc'!U14 -> 82993.155 | N14: =IF(OR(NOT(ISNUMBER(L14)),NOT(ISNUMBER(M14)),L14+M14=0),"",L14/(L14+M14)) -> 0.5 | O14: =IF(NOT(ISNUMBER(N14)),"",IF(K14="A",MIN(Parameters!$B$8,N14+Parameters!$B$6),IF(K14="B",MAX(Parameters!$B$7,N14-Parameters!$B$6),N14))) -> 0.5 | P14: =IF(NOT(ISNUMBER(O14)),"",MAX(0,L14-(L14+M14)*O14)) -> 0 | Q14: =IF(NOT(ISNUMBER(O14)),"",MAX(0,(L14+M14)*O14-L14)) -> 0 | R14: =IF(NOT(ISNUMBER(O14)),"",L14-P14+Q14) -> 82993.155 | S14: =IF(NOT(ISNUMBER(O14)),"",M14+P14-Q14) -> 82993.155 | T14: =IF(OR(NOT(ISNUMBER(R14)),NOT(ISNUMBER(S14)),R14+S14=0),"",R14/(R14+S14)) -> 0.5 | U14: =IF(NOT(ISNUMBER(O14)),"",IF(P14>0.005,"Transfer "&TEXT(P14,"#,##0.00")&" A → B",IF(Q14>0.005,"Transfer "&TEXT(Q14,"#,##0.00")&" B → A","No transfer"))) -> No transfer | V14: Historical
A15: 43283 | B15: 0.01655 | C15: 0 | D15: =IF(AND(ISNUMBER(B15),ISNUMBER(C15)),(B15+C15)/2,"") -> 0.008275 | E15: ="" | F15: ="" | G15: ="" | H15: =IF(AND(ISNUMBER(F15),ISNUMBER(G15)),F15-G15,"") | I15: =IF(OR(NOT(ISNUMBER(F15)),NOT(ISNUMBER(G15))),"",IF(F15>G15,"A",IF(G15>F15,"B","HOLD"))) | J15: =IF(I15="","",IF(I15="HOLD",0,IF(I15=I14,J14+1,1))) | K15: =IF(I15="","",IF(J15>=Parameters!$B$5,I15,"HOLD")) | L15: ='Actual Calc'!T15 -> 101302.42 | M15: ='Actual Calc'!U15 -> 82993.155 | N15: =IF(OR(NOT(ISNUMBER(L15)),NOT(ISNUMBER(M15)),L15+M15=0),"",L15/(L15+M15)) -> 0.54967364 | O15: =IF(NOT(ISNUMBER(N15)),"",IF(K15="A",MIN(Parameters!$B$8,N15+Parameters!$B$6),IF(K15="B",MAX(Parameters!$B$7,N15-Parameters!$B$6),N15))) -> 0.54967364 | P15: =IF(NOT(ISNUMBER(O15)),"",MAX(0,L15-(L15+M15)*O15)) -> 0 | Q15: =IF(NOT(ISNUMBER(O15)),"",MAX(0,(L15+M15)*O15-L15)) -> 1.4551915e-11 | R15: =IF(NOT(ISNUMBER(O15)),"",L15-P15+Q15) -> 101302.42 | S15: =IF(NOT(ISNUMBER(O15)),"",M15+P15-Q15) -> 82993.155 | T15: =IF(OR(NOT(ISNUMBER(R15)),NOT(ISNUMBER(S15)),R15+S15=0),"",R15/(R15+S15)) -> 0.54967364 | U15: =IF(NOT(ISNUMBER(O15)),"",IF(P15>0.005,"Transfer "&TEXT(P15,"#,##0.00")&" A → B",IF(Q15>0.005,"Transfer "&TEXT(Q15,"#,##0.00")&" B → A","No transfer"))) -> No transfer | V15: Historical | B SKIP
A16: 43290 | B16: 0.01753 | C16: 0.01753 | D16: =IF(AND(ISNUMBER(B16),ISNUMBER(C16)),(B16+C16)/2,"") -> 0.01753 | E16: ="" | F16: ="" | G16: ="" | H16: =IF(AND(ISNUMBER(F16),ISNUMBER(G16)),F16-G16,"") | I16: =IF(OR(NOT(ISNUMBER(F16)),NOT(ISNUMBER(G16))),"",IF(F16>G16,"A",IF(G16>F16,"B","HOLD"))) | J16: =IF(I16="","",IF(I16="HOLD",0,IF(I16=I15,J15+1,1))) | K16: =IF(I16="","",IF(J16>=Parameters!$B$5,I16,"HOLD")) | L16: ='Actual Calc'!T16 -> 124969.67 | M16: ='Actual Calc'!U16 -> 102386.59 | N16: =IF(OR(NOT(ISNUMBER(L16)),NOT(ISNUMBER(M16)),L16+M16=0),"",L16/(L16+M16)) -> 0.54966452 | O16: =IF(NOT(ISNUMBER(N16)),"",IF(K16="A",MIN(Parameters!$B$8,N16+Parameters!$B$6),IF(K16="B",MAX(Parameters!$B$7,N16-Parameters!$B$6),N16))) -> 0.54966452 | P16: =IF(NOT(ISNUMBER(O16)),"",MAX(0,L16-(L16+M16)*O16)) -> 0 | Q16: =IF(NOT(ISNUMBER(O16)),"",MAX(0,(L16+M16)*O16-L16)) -> 0 | R16: =IF(NOT(ISNUMBER(O16)),"",L16-P16+Q16) -> 124969.67 | S16: =IF(NOT(ISNUMBER(O16)),"",M16+P16-Q16) -> 102386.59 | T16: =IF(OR(NOT(ISNUMBER(R16)),NOT(ISNUMBER(S16)),R16+S16=0),"",R16/(R16+S16)) -> 0.54966452 | U16: =IF(NOT(ISNUMBER(O16)),"",IF(P16>0.005,"Transfer "&TEXT(P16,"#,##0.00")&" A → B",IF(Q16>0.005,"Transfer "&TEXT(Q16,"#,##0.00")&" B → A","No transfer"))) -> No transfer | V16: Historical
... A28: 43374 | B28: -0.0038 | C28: -0.0038 | D28: =IF(AND(ISNUMBER(B28),ISNUMBER(C28)),(B28+C28)/2,"") -> -0.0038 | E28: ="" | F28: ="" | G28: ="" | H28: =IF(AND(ISNUMBER(F28),ISNUMBER(G28)),F28-G28,"") | I28: =IF(OR(NOT(ISNUMBER(F28)),NOT(ISNUMBER(G28))),"",IF(F28>G28,"A",IF(G28>F28,"B","HOLD"))) | J28: =IF(I28="","",IF(I28="HOLD",0,IF(I28=I27,J27+1,1))) | K28: =IF(I28="","",IF(J28>=Parameters!$B$5,I28,"HOLD")) | L28: ='Actual Calc'!T28 -> 172132.35 | M28: ='Actual Calc'!U28 -> 172269.54 | N28: =IF(OR(NOT(ISNUMBER(L28)),NOT(ISNUMBER(M28)),L28+M28=0),"",L28/(L28+M28)) -> 0.49980082 | O28: =IF(NOT(ISNUMBER(N28)),"",IF(K28="A",MIN(Parameters!$B$8,N28+Parameters!$B$6),IF(K28="B",MAX(Parameters!$B$7,N28-Parameters!$B$6),N28))) -> 0.49980082 | P28: =IF(NOT(ISNUMBER(O28)),"",MAX(0,L28-(L28+M28)*O28)) -> 0 | Q28: =IF(NOT(ISNUMBER(O28)),"",MAX(0,(L28+M28)*O28-L28)) -> 0 | R28: =IF(NOT(ISNUMBER(O28)),"",L28-P28+Q28) -> 172132.35 | S28: =IF(NOT(ISNUMBER(O28)),"",M28+P28-Q28) -> 172269.54 | T28: =IF(OR(NOT(ISNUMBER(R28)),NOT(ISNUMBER(S28)),R28+S28=0),"",R28/(R28+S28)) -> 0.49980082 | U28: =IF(NOT(ISNUMBER(O28)),"",IF(P28>0.005,"Transfer "&TEXT(P28,"#,##0.00")&" A → B",IF(Q28>0.005,"Transfer "&TEXT(Q28,"#,##0.00")&" B → A","No transfer"))) -> No transfer | V28: Historical
A29: 43381 | B29: -0.05094 | C29: 0 | D29: =IF(AND(ISNUMBER(B29),ISNUMBER(C29)),(B29+C29)/2,"") -> -0.02547 | E29: =IF(NOT(ISNUMBER(D29)),"",COUNTIF(D4:D29,">0")) -> 13 | F29: =IF(OR(NOT(ISNUMBER(E29)),E29<2),"",IFERROR((SUMPRODUCT(--(D4:D29>0),B4:B29,D4:D29)-SUMPRODUCT(--(D4:D29>0),B4:B29)*SUMPRODUCT(--(D4:D29>0),D4:D29)/E29)/(SUMPRODUCT(--(D4:D29>0),D4:D29,D4:D29)-SUMPRODUCT(--(D4:D29>0),D4:D29)^2/E29),"")) -> 0.89944457 | G29: =IF(OR(NOT(ISNUMBER(E29)),E29<2),"",IFERROR((SUMPRODUCT(--(D4:D29>0),C4:C29,D4:D29)-SUMPRODUCT(--(D4:D29>0),C4:C29)*SUMPRODUCT(--(D4:D29>0),D4:D29)/E29)/(SUMPRODUCT(--(D4:D29>0),D4:D29,D4:D29)-SUMPRODUCT(--(D4:D29>0),D4:D29)^2/E29),"")) -> 1.1005554 | H29: =IF(AND(ISNUMBER(F29),ISNUMBER(G29)),F29-G29,"") -> -0.20111087 | I29: =IF(OR(NOT(ISNUMBER(F29)),NOT(ISNUMBER(G29))),"",IF(F29>G29,"A",IF(G29>F29,"B","HOLD"))) -> B | J29: =IF(I29="","",IF(I29="HOLD",0,IF(I29=I28,J28+1,1))) -> 1 | K29: =IF(I29="","",IF(J29>=Parameters!$B$5,I29,"HOLD")) -> HOLD | L29: ='Actual Calc'!T29 -> 55321.832 | M29: ='Actual Calc'!U29 -> 172269.54 | N29: =IF(OR(NOT(ISNUMBER(L29)),NOT(ISNUMBER(M29)),L29+M29=0),"",L29/(L29+M29)) -> 0.24307526 | O29: =IF(NOT(ISNUMBER(N29)),"",IF(K29="A",MIN(Parameters!$B$8,N29+Parameters!$B$6),IF(K29="B",MAX(Parameters!$B$7,N29-Parameters!$B$6),N29))) -> 0.24307526 | P29: =IF(NOT(ISNUMBER(O29)),"",MAX(0,L29-(L29+M29)*O29)) -> 0 | Q29: =IF(NOT(ISNUMBER(O29)),"",MAX(0,(L29+M29)*O29-L29)) -> 0 | R29: =IF(NOT(ISNUMBER(O29)),"",L29-P29+Q29) -> 55321.832 | S29: =IF(NOT(ISNUMBER(O29)),"",M29+P29-Q29) -> 172269.54 | T29: =IF(OR(NOT(ISNUMBER(R29)),NOT(ISNUMBER(S29)),R29+S29=0),"",R29/(R29+S29)) -> 0.24307526 | U29: =IF(NOT(ISNUMBER(O29)),"",IF(P29>0.005,"Transfer "&TEXT(P29,"#,##0.00")&" A → B",IF(Q29>0.005,"Transfer "&TEXT(Q29,"#,##0.00")&" B → A","No transfer"))) -> No transfer | V29: Historical | B SKIP
A30: 43388 | B30: -0.004 | C30: -0.004 | D30: =IF(AND(ISNUMBER(B30),ISNUMBER(C30)),(B30+C30)/2,"") -> -0.004 | E30: =IF(NOT(ISNUMBER(D30)),"",COUNTIF(D5:D30,">0")) -> 12 | F30: =IF(OR(NOT(ISNUMBER(E30)),E30<2),"",IFERROR((SUMPRODUCT(--(D5:D30>0),B5:B30,D5:D30)-SUMPRODUCT(--(D5:D30>0),B5:B30)*SUMPRODUCT(--(D5:D30>0),D5:D30)/E30)/(SUMPRODUCT(--(D5:D30>0),D5:D30,D5:D30)-SUMPRODUCT(--(D5:D30>0),D5:D30)^2/E30),"")) -> 0.89643627 | G30: =IF(OR(NOT(ISNUMBER(E30)),E30<2),"",IFERROR((SUMPRODUCT(--(D5:D30>0),C5:C30,D5:D30)-SUMPRODUCT(--(D5:D30>0),C5:C30)*SUMPRODUCT(--(D5:D30>0),D5:D30)/E30)/(SUMPRODUCT(--(D5:D30>0),D5:D30,D5:D30)-SUMPRODUCT(--(D5:D30>0),D5:D30)^2/E30),"")) -> 1.1035637 | H30: =IF(AND(ISNUMBER(F30),ISNUMBER(G30)),F30-G30,"") -> -0.20712747 | I30: =IF(OR(NOT(ISNUMBER(F30)),NOT(ISNUMBER(G30))),"",IF(F30>G30,"A",IF(G30>F30,"B","HOLD"))) -> B | J30: =IF(I30="","",IF(I30="HOLD",0,IF(I30=I29,J29+1,1))) -> 2 | K30: =IF(I30="","",IF(J30>=Parameters!$B$5,I30,"HOLD")) -> HOLD | L30: ='Actual Calc'!T30 -> 52377.832 | M30: ='Actual Calc'!U30 -> 163087.94 | N30: =IF(OR(NOT(ISNUMBER(L30)),NOT(ISNUMBER(M30)),L30+M30=0),"",L30/(L30+M30)) -> 0.24309119 | O30: =IF(NOT(ISNUMBER(N30)),"",IF(K30="A",MIN(Parameters!$B$8,N30+Parameters!$B$6),IF(K30="B",MAX(Parameters!$B$7,N30-Parameters!$B$6),N30))) -> 0.24309119 | P30: =IF(NOT(ISNUMBER(O30)),"",MAX(0,L30-(L30+M30)*O30)) -> 0 | Q30: =IF(NOT(ISNUMBER(O30)),"",MAX(0,(L30+M30)*O30-L30)) -> 0 | R30: =IF(NOT(ISNUMBER(O30)),"",L30-P30+Q30) -> 52377.832 | S30: =IF(NOT(ISNUMBER(O30)),"",M30+P30-Q30) -> 163087.94 | T30: =IF(OR(NOT(ISNUMBER(R30)),NOT(ISNUMBER(S30)),R30+S30=0),"",R30/(R30+S30)) -> 0.24309119 | U30: =IF(NOT(ISNUMBER(O30)),"",IF(P30>0.005,"Transfer "&TEXT(P30,"#,##0.00")&" A → B",IF(Q30>0.005,"Transfer "&TEXT(Q30,"#,##0.00")&" B → A","No transfer"))) -> No transfer | V30: Historical
A31: 43395 | B31: -0.00319 | C31: -0.00319 | D31: =IF(AND(ISNUMBER(B31),ISNUMBER(C31)),(B31+C31)/2,"") -> -0.00319 | E31: =IF(NOT(ISNUMBER(D31)),"",COUNTIF(D6:D31,">0")) -> 12 | F31: =IF(OR(NOT(ISNUMBER(E31)),E31<2),"",IFERROR((SUMPRODUCT(--(D6:D31>0),B6:B31,D6:D31)-SUMPRODUCT(--(D6:D31>0),B6:B31)*SUMPRODUCT(--(D6:D31>0),D6:D31)/E31)/(SUMPRODUCT(--(D6:D31>0),D6:D31,D6:D31)-SUMPRODUCT(--(D6:D31>0),D6:D31)^2/E31),"")) -> 0.89643627 | G31: =IF(OR(NOT(ISNUMBER(E31)),E31<2),"",IFERROR((SUMPRODUCT(--(D6:D31>0),C6:C31,D6:D31)-SUMPRODUCT(--(D6:D31>0),C6:C31)*SUMPRODUCT(--(D6:D31>0),D6:D31)/E31)/(SUMPRODUCT(--(D6:D31>0),D6:D31,D6:D31)-SUMPRODUCT(--(D6:D31>0),D6:D31)^2/E31),"")) -> 1.1035637 | H31: =IF(AND(ISNUMBER(F31),ISNUMBER(G31)),F31-G31,"") -> -0.20712747 | I31: =IF(OR(NOT(ISNUMBER(F31)),NOT(ISNUMBER(G31))),"",IF(F31>G31,"A",IF(G31>F31,"B","HOLD"))) -> B | J31: =IF(I31="","",IF(I31="HOLD",0,IF(I31=I30,J30+1,1))) -> 3 | K31: =IF(I31="","",IF(J31>=Parameters!$B$5,I31,"HOLD")) -> B | L31: ='Actual Calc'!T31 -> 50154.721 | M31: ='Actual Calc'!U31 -> 156154.48 | N31: =IF(OR(NOT(ISNUMBER(L31)),NOT(ISNUMBER(M31)),L31+M31=0),"",L31/(L31+M31)) -> 0.24310463 | O31: =IF(NOT(ISNUMBER(N31)),"",IF(K31="A",MIN(Parameters!$B$8,N31+Parameters!$B$6),IF(K31="B",MAX(Parameters!$B$7,N31-Parameters!$B$6),N31))) -> 0.14310463 | P31: =IF(NOT(ISNUMBER(O31)),"",MAX(0,L31-(L31+M31)*O31)) -> 20630.92 | Q31: =IF(NOT(ISNUMBER(O31)),"",MAX(0,(L31+M31)*O31-L31)) -> 0 | R31: =IF(NOT(ISNUMBER(O31)),"",L31-P31+Q31) -> 29523.801 | S31: =IF(NOT(ISNUMBER(O31)),"",M31+P31-Q31) -> 176785.4 | T31: =IF(OR(NOT(ISNUMBER(R31)),NOT(ISNUMBER(S31)),R31+S31=0),"",R31/(R31+S31)) -> 0.14310463 | U31: =IF(NOT(ISNUMBER(O31)),"",IF(P31>0.005,"Transfer "&TEXT(P31,"#,##0.00")&" A → B",IF(Q31>0.005,"Transfer "&TEXT(Q31,"#,##0.00")&" B → A","No transfer"))) -> #VALUE! | V31: Historical
A32: 43402 | B32: -0.0038 | C32: 0 | D32: =IF(AND(ISNUMBER(B32),ISNUMBER(C32)),(B32+C32)/2,"") -> -0.0019 | E32: =IF(NOT(ISNUMBER(D32)),"",COUNTIF(D7:D32,">0")) -> 12 | F32: =IF(OR(NOT(ISNUMBER(E32)),E32<2),"",IFERROR((SUMPRODUCT(--(D7:D32>0),B7:B32,D7:D32)-SUMPRODUCT(--(D7:D32>0),B7:B32)*SUMPRODUCT(--(D7:D32>0),D7:D32)/E32)/(SUMPRODUCT(--(D7:D32>0),D7:D32,D7:D32)-SUMPRODUCT(--(D7:D32>0),D7:D32)^2/E32),"")) -> 0.89643627 | G32: =IF(OR(NOT(ISNUMBER(E32)),E32<2),"",IFERROR((SUMPRODUCT(--(D7:D32>0),C7:C32,D7:D32)-SUMPRODUCT(--(D7:D32>0),C7:C32)*SUMPRODUCT(--(D7:D32>0),D7:D32)/E32)/(SUMPRODUCT(--(D7:D32>0),D7:D32,D7:D32)-SUMPRODUCT(--(D7:D32>0),D7:D32)^2/E32),"")) -> 1.1035637 | H32: =IF(AND(ISNUMBER(F32),ISNUMBER(G32)),F32-G32,"") -> -0.20712747 | I32: =IF(OR(NOT(ISNUMBER(F32)),NOT(ISNUMBER(G32))),"",IF(F32>G32,"A",IF(G32>F32,"B","HOLD"))) -> B | J32: =IF(I32="","",IF(I32="HOLD",0,IF(I32=I31,J31+1,1))) -> 4 | K32: =IF(I32="","",IF(J32>=Parameters!$B$5,I32,"HOLD")) -> B | L32: ='Actual Calc'!T32 -> 28029.261 | M32: ='Actual Calc'!U32 -> 176785.4 | N32: =IF(OR(NOT(ISNUMBER(L32)),NOT(ISNUMBER(M32)),L32+M32=0),"",L32/(L32+M32)) -> 0.13685183 | O32: =IF(NOT(ISNUMBER(N32)),"",IF(K32="A",MIN(Parameters!$B$8,N32+Parameters!$B$6),IF(K32="B",MAX(Parameters!$B$7,N32-Parameters!$B$6),N32))) -> 0.036851833 | P32: =IF(NOT(ISNUMBER(O32)),"",MAX(0,L32-(L32+M32)*O32)) -> 20481.466 | Q32: =IF(NOT(ISNUMBER(O32)),"",MAX(0,(L32+M32)*O32-L32)) -> 0 | R32: =IF(NOT(ISNUMBER(O32)),"",L32-P32+Q32) -> 7547.7956 | S32: =IF(NOT(ISNUMBER(O32)),"",M32+P32-Q32) -> 197266.86 | T32: =IF(OR(NOT(ISNUMBER(R32)),NOT(ISNUMBER(S32)),R32+S32=0),"",R32/(R32+S32)) -> 0.036851833 | U32: =IF(NOT(ISNUMBER(O32)),"",IF(P32>0.005,"Transfer "&TEXT(P32,"#,##0.00")&" A → B",IF(Q32>0.005,"Transfer "&TEXT(Q32,"#,##0.00")&" B → A","No transfer"))) -> #VALUE! | V32: Historical | B SKIP
A33: 43409 | B33: 0.00994 | C33: 0.00994 | D33: =IF(AND(ISNUMBER(B33),ISNUMBER(C33)),(B33+C33)/2,"") -> 0.00994 | E33: =IF(NOT(ISNUMBER(D33)),"",COUNTIF(D8:D33,">0")) -> 12 | F33: =IF(OR(NOT(ISNUMBER(E33)),E33<2),"",IFERROR((SUMPRODUCT(--(D8:D33>0),B8:B33,D8:D33)-SUMPRODUCT(--(D8:D33>0),B8:B33)*SUMPRODUCT(--(D8:D33>0),D8:D33)/E33)/(SUMPRODUCT(--(D8:D33>0),D8:D33,D8:D33)-SUMPRODUCT(--(D8:D33>0),D8:D33)^2/E33),"")) -> 0.89385443 | G33: =IF(OR(NOT(ISNUMBER(E33)),E33<2),"",IFERROR((SUMPRODUCT(--(D8:D33>0),C8:C33,D8:D33)-SUMPRODUCT(--(D8:D33>0),C8:C33)*SUMPRODUCT(--(D8:D33>0),D8:D33)/E33)/(SUMPRODUCT(--(D8:D33>0),D8:D33,D8:D33)-SUMPRODUCT(--(D8:D33>0),D8:D33)^2/E33),"")) -> 1.1061456 | H33: =IF(AND(ISNUMBER(F33),ISNUMBER(G33)),F33-G33,"") -> -0.21229113 | I33: =IF(OR(NOT(ISNUMBER(F33)),NOT(ISNUMBER(G33))),"",IF(F33>G33,"A",IF(G33>F33,"B","HOLD"))) -> B | J33: =IF(I33="","",IF(I33="HOLD",0,IF(I33=I32,J32+1,1))) -> 5 | K33: =IF(I33="","",IF(J33>=Parameters!$B$5,I33,"HOLD")) -> B | L33: ='Actual Calc'!T33 -> 8530.8616 | M33: ='Actual Calc'!U33 -> 223398.13 | N33: =IF(OR(NOT(ISNUMBER(L33)),NOT(ISNUMBER(M33)),L33+M33=0),"",L33/(L33+M33)) -> 0.036782214 | O33: =IF(NOT(ISNUMBER(N33)),"",IF(K33="A",MIN(Parameters!$B$8,N33+Parameters!$B$6),IF(K33="B",MAX(Parameters!$B$7,N33-Parameters!$B$6),N33))) -> 0 | P33: =IF(NOT(ISNUMBER(O33)),"",MAX(0,L33-(L33+M33)*O33)) -> 8530.8616 | Q33: =IF(NOT(ISNUMBER(O33)),"",MAX(0,(L33+M33)*O33-L33)) -> 0 | R33: =IF(NOT(ISNUMBER(O33)),"",L33-P33+Q33) -> 0 | S33: =IF(NOT(ISNUMBER(O33)),"",M33+P33-Q33) -> 231928.99 | T33: =IF(OR(NOT(ISNUMBER(R33)),NOT(ISNUMBER(S33)),R33+S33=0),"",R33/(R33+S33)) -> 0 | U33: =IF(NOT(ISNUMBER(O33)),"",IF(P33>0.005,"Transfer "&TEXT(P33,"#,##0.00")&" A → B",IF(Q33>0.005,"Transfer "&TEXT(Q33,"#,##0.00")&" B → A","No transfer"))) -> #VALUE! | V33: Historical
A34: 43416 | B34: -0.03088 | C34: 0 | D34: =IF(AND(ISNUMBER(B34),ISNUMBER(C34)),(B34+C34)/2,"") -> -0.01544 | E34: =IF(NOT(ISNUMBER(D34)),"",COUNTIF(D9:D34,">0")) -> 12 | F34: =IF(OR(NOT(ISNUMBER(E34)),E34<2),"",IFERROR((SUMPRODUCT(--(D9:D34>0),B9:B34,D9:D34)-SUMPRODUCT(--(D9:D34>0),B9:B34)*SUMPRODUCT(--(D9:D34>0),D9:D34)/E34)/(SUMPRODUCT(--(D9:D34>0),D9:D34,D9:D34)-SUMPRODUCT(--(D9:D34>0),D9:D34)^2/E34),"")) -> 0.89385443 | G34: =IF(OR(NOT(ISNUMBER(E34)),E34<2),"",IFERROR((SUMPRODUCT(--(D9:D34>0),C9:C34,D9:D34)-SUMPRODUCT(--(D9:D34>0),C9:C34)*SUMPRODUCT(--(D9:D34>0),D9:D34)/E34)/(SUMPRODUCT(--(D9:D34>0),D9:D34,D9:D34)-SUMPRODUCT(--(D9:D34>0),D9:D34)^2/E34),"")) -> 1.1061456 | H34: =IF(AND(ISNUMBER(F34),ISNUMBER(G34)),F34-G34,"") -> -0.21229113 | I34: =IF(OR(NOT(ISNUMBER(F34)),NOT(ISNUMBER(G34))),"",IF(F34>G34,"A",IF(G34>F34,"B","HOLD"))) -> B | J34: =IF(I34="","",IF(I34="HOLD",0,IF(I34=I33,J33+1,1))) -> 6 | K34: =IF(I34="","",IF(J34>=Parameters!$B$5,I34,"HOLD")) -> B | L34: ='Actual Calc'!T34 -> 0 | M34: ='Actual Calc'!U34 -> 231928.99 | N34: =IF(OR(NOT(ISNUMBER(L34)),NOT(ISNUMBER(M34)),L34+M34=0),"",L34/(L34+M34)) -> 0 | O34: =IF(NOT(ISNUMBER(N34)),"",IF(K34="A",MIN(Parameters!$B$8,N34+Parameters!$B$6),IF(K34="B",MAX(Parameters!$B$7,N34-Parameters!$B$6),N34))) -> 0 | P34: =IF(NOT(ISNUMBER(O34)),"",MAX(0,L34-(L34+M34)*O34)) -> 0 | Q34: =IF(NOT(ISNUMBER(O34)),"",MAX(0,(L34+M34)*O34-L34)) -> 0 | R34: =IF(NOT(ISNUMBER(O34)),"",L34-P34+Q34) -> 0 | S34: =IF(NOT(ISNUMBER(O34)),"",M34+P34-Q34) -> 231928.99 | T34: =IF(OR(NOT(ISNUMBER(R34)),NOT(ISNUMBER(S34)),R34+S34=0),"",R34/(R34+S34)) -> 0 | U34: =IF(NOT(ISNUMBER(O34)),"",IF(P34>0.005,"Transfer "&TEXT(P34,"#,##0.00")&" A → B",IF(Q34>0.005,"Transfer "&TEXT(Q34,"#,##0.00")&" B → A","No transfer"))) -> No transfer | V34: Historical | B SKIP
A35: 43423 | B35: -0.05419 | C35: 0 | D35: =IF(AND(ISNUMBER(B35),ISNUMBER(C35)),(B35+C35)/2,"") -> -0.027095 | E35: =IF(NOT(ISNUMBER(D35)),"",COUNTIF(D10:D35,">0")) -> 12 | F35: =IF(OR(NOT(ISNUMBER(E35)),E35<2),"",IFERROR((SUMPRODUCT(--(D10:D35>0),B10:B35,D10:D35)-SUMPRODUCT(--(D10:D35>0),B10:B35)*SUMPRODUCT(--(D10:D35>0),D10:D35)/E35)/(SUMPRODUCT(--(D10:D35>0),D10:D35,D10:D35)-SUMPRODUCT(--(D10:D35>0),D10:D35)^2/E35),"")) -> 0.89385443 | G35: =IF(OR(NOT(ISNUMBER(E35)),E35<2),"",IFERROR((SUMPRODUCT(--(D10:D35>0),C10:C35,D10:D35)-SUMPRODUCT(--(D10:D35>0),C10:C35)*SUMPRODUCT(--(D10:D35>0),D10:D35)/E35)/(SUMPRODUCT(--(D10:D35>0),D10:D35,D10:D35)-SUMPRODUCT(--(D10:D35>0),D10:D35)^2/E35),"")) -> 1.1061456 | H35: =IF(AND(ISNUMBER(F35),ISNUMBER(G35)),F35-G35,"") -> -0.21229113 | I35: =IF(OR(NOT(ISNUMBER(F35)),NOT(ISNUMBER(G35))),"",IF(F35>G35,"A",IF(G35>F35,"B","HOLD"))) -> B | J35: =IF(I35="","",IF(I35="HOLD",0,IF(I35=I34,J34+1,1))) -> 7 | K35: =IF(I35="","",IF(J35>=Parameters!$B$5,I35,"HOLD")) -> B | L35: ='Actual Calc'!T35 -> 0 | M35: ='Actual Calc'!U35 -> 231928.99 | N35: =IF(OR(NOT(ISNUMBER(L35)),NOT(ISNUMBER(M35)),L35+M35=0),"",L35/(L35+M35)) -> 0 | O35: =IF(NOT(ISNUMBER(N35)),"",IF(K35="A",MIN(Parameters!$B$8,N35+Parameters!$B$6),IF(K35="B",MAX(Parameters!$B$7,N35-Parameters!$B$6),N35))) -> 0 | P35: =IF(NOT(ISNUMBER(O35)),"",MAX(0,L35-(L35+M35)*O35)) -> 0 | Q35: =IF(NOT(ISNUMBER(O35)),"",MAX(0,(L35+M35)*O35-L35)) -> 0 | R35: =IF(NOT(ISNUMBER(O35)),"",L35-P35+Q35) -> 0 | S35: =IF(NOT(ISNUMBER(O35)),"",M35+P35-Q35) -> 231928.99 | T35: =IF(OR(NOT(ISNUMBER(R35)),NOT(ISNUMBER(S35)),R35+S35=0),"",R35/(R35+S35)) -> 0 | U35: =IF(NOT(ISNUMBER(O35)),"",IF(P35>0.005,"Transfer "&TEXT(P35,"#,##0.00")&" A → B",IF(Q35>0.005,"Transfer "&TEXT(Q35,"#,##0.00")&" B → A","No transfer"))) -> No transfer | V35: Historical | B SKIP
A36: 43430 | B36: 0.0105 | C36: 0 | D36: =IF(AND(ISNUMBER(B36),ISNUMBER(C36)),(B36+C36)/2,"") -> 0.00525 | E36: =IF(NOT(ISNUMBER(D36)),"",COUNTIF(D11:D36,">0")) -> 12 | F36: =IF(OR(NOT(ISNUMBER(E36)),E36<2),"",IFERROR((SUMPRODUCT(--(D11:D36>0),B11:B36,D11:D36)-SUMPRODUCT(--(D11:D36>0),B11:B36)*SUMPRODUCT(--(D11:D36>0),D11:D36)/E36)/(SUMPRODUCT(--(D11:D36>0),D11:D36,D11:D36)-SUMPRODUCT(--(D11:D36>0),D11:D36)^2/E36),"")) -> 0.77751975 | G36: =IF(OR(NOT(ISNUMBER(E36)),E36<2),"",IFERROR((SUMPRODUCT(--(D11:D36>0),C11:C36,D11:D36)-SUMPRODUCT(--(D11:D36>0),C11:C36)*SUMPRODUCT(--(D11:D36>0),D11:D36)/E36)/(SUMPRODUCT(--(D11:D36>0),D11:D36,D11:D36)-SUMPRODUCT(--(D11:D36>0),D11:D36)^2/E36),"")) -> 1.2224802 | H36: =IF(AND(ISNUMBER(F36),ISNUMBER(G36)),F36-G36,"") -> -0.4449605 | I36: =IF(OR(NOT(ISNUMBER(F36)),NOT(ISNUMBER(G36))),"",IF(F36>G36,"A",IF(G36>F36,"B","HOLD"))) -> B | J36: =IF(I36="","",IF(I36="HOLD",0,IF(I36=I35,J35+1,1))) -> 8 | K36: =IF(I36="","",IF(J36>=Parameters!$B$5,I36,"HOLD")) -> B | L36: ='Actual Calc'!T36 -> 0 | M36: ='Actual Calc'!U36 -> 231928.99 | N36: =IF(OR(NOT(ISNUMBER(L36)),NOT(ISNUMBER(M36)),L36+M36=0),"",L36/(L36+M36)) -> 0 | O36: =IF(NOT(ISNUMBER(N36)),"",IF(K36="A",MIN(Parameters!$B$8,N36+Parameters!$B$6),IF(K36="B",MAX(Parameters!$B$7,N36-Parameters!$B$6),N36))) -> 0 | P36: =IF(NOT(ISNUMBER(O36)),"",MAX(0,L36-(L36+M36)*O36)) -> 0 | Q36: =IF(NOT(ISNUMBER(O36)),"",MAX(0,(L36+M36)*O36-L36)) -> 0 | R36: =IF(NOT(ISNUMBER(O36)),"",L36-P36+Q36) -> 0 | S36: =IF(NOT(ISNUMBER(O36)),"",M36+P36-Q36) -> 231928.99 | T36: =IF(OR(NOT(ISNUMBER(R36)),NOT(ISNUMBER(S36)),R36+S36=0),"",R36/(R36+S36)) -> 0 | U36: =IF(NOT(ISNUMBER(O36)),"",IF(P36>0.005,"Transfer "&TEXT(P36,"#,##0.00")&" A → B",IF(Q36>0.005,"Transfer "&TEXT(Q36,"#,##0.00")&" B → A","No transfer"))) -> No transfer | V36: Historical | B SKIP
A37: 43437 | B37: -0.03736 | C37: 0 | D37: =IF(AND(ISNUMBER(B37),ISNUMBER(C37)),(B37+C37)/2,"") -> -0.01868 | E37: =IF(NOT(ISNUMBER(D37)),"",COUNTIF(D12:D37,">0")) -> 11 | F37: =IF(OR(NOT(ISNUMBER(E37)),E37<2),"",IFERROR((SUMPRODUCT(--(D12:D37>0),B12:B37,D12:D37)-SUMPRODUCT(--(D12:D37>0),B12:B37)*SUMPRODUCT(--(D12:D37>0),D12:D37)/E37)/(SUMPRODUCT(--(D12:D37>0),D12:D37,D12:D37)-SUMPRODUCT(--(D12:D37>0),D12:D37)^2/E37),"")) -> 0.74599662 | G37: =IF(OR(NOT(ISNUMBER(E37)),E37<2),"",IFERROR((SUMPRODUCT(--(D12:D37>0),C12:C37,D12:D37)-SUMPRODUCT(--(D12:D37>0),C12:C37)*SUMPRODUCT(--(D12:D37>0),D12:D37)/E37)/(SUMPRODUCT(--(D12:D37>0),D12:D37,D12:D37)-SUMPRODUCT(--(D12:D37>0),D12:D37)^2/E37),"")) -> 1.2540034 | H37: =IF(AND(ISNUMBER(F37),ISNUMBER(G37)),F37-G37,"") -> -0.50800676 | I37: =IF(OR(NOT(ISNUMBER(F37)),NOT(ISNUMBER(G37))),"",IF(F37>G37,"A",IF(G37>F37,"B","HOLD"))) -> B | J37: =IF(I37="","",IF(I37="HOLD",0,IF(I37=I36,J36+1,1))) -> 9 | K37: =IF(I37="","",IF(J37>=Parameters!$B$5,I37,"HOLD")) -> B | L37: ='Actual Calc'!T37 -> 0 | M37: ='Actual Calc'!U37 -> 231928.99 | N37: =IF(OR(NOT(ISNUMBER(L37)),NOT(ISNUMBER(M37)),L37+M37=0),"",L37/(L37+M37)) -> 0 | O37: =IF(NOT(ISNUMBER(N37)),"",IF(K37="A",MIN(Parameters!$B$8,N37+Parameters!$B$6),IF(K37="B",MAX(Parameters!$B$7,N37-Parameters!$B$6),N37))) -> 0 | P37: =IF(NOT(ISNUMBER(O37)),"",MAX(0,L37-(L37+M37)*O37)) -> 0 | Q37: =IF(NOT(ISNUMBER(O37)),"",MAX(0,(L37+M37)*O37-L37)) -> 0 | R37: =IF(NOT(ISNUMBER(O37)),"",L37-P37+Q37) -> 0 | S37: =IF(NOT(ISNUMBER(O37)),"",M37+P37-Q37) -> 231928.99 | T37: =IF(OR(NOT(ISNUMBER(R37)),NOT(ISNUMBER(S37)),R37+S37=0),"",R37/(R37+S37)) -> 0 | U37: =IF(NOT(ISNUMBER(O37)),"",IF(P37>0.005,"Transfer "&TEXT(P37,"#,##0.00")&" A → B",IF(Q37>0.005,"Transfer "&TEXT(Q37,"#,##0.00")&" B → A","No transfer"))) -> No transfer | V37: Historical | B SKIP
A38: 43444 | B38: 0.01346 | C38: -0.00687 | D38: =IF(AND(ISNUMBER(B38),ISNUMBER(C38)),(B38+C38)/2,"") -> 0.003295 | E38: =IF(NOT(ISNUMBER(D38)),"",COUNTIF(D13:D38,">0")) -> 11 | F38: =IF(OR(NOT(ISNUMBER(E38)),E38<2),"",IFERROR((SUMPRODUCT(--(D13:D38>0),B13:B38,D13:D38)-SUMPRODUCT(--(D13:D38>0),B13:B38)*SUMPRODUCT(--(D13:D38>0),D13:D38)/E38)/(SUMPRODUCT(--(D13:D38>0),D13:D38,D13:D38)-SUMPRODUCT(--(D13:D38>0),D13:D38)^2/E38),"")) -> 0.55350217 | G38: =IF(OR(NOT(ISNUMBER(E38)),E38<2),"",IFERROR((SUMPRODUCT(--(D13:D38>0),C13:C38,D13:D38)-SUMPRODUCT(--(D13:D38>0),C13:C38)*SUMPRODUCT(--(D13:D38>0),D13:D38)/E38)/(SUMPRODUCT(--(D13:D38>0),D13:D38,D13:D38)-SUMPRODUCT(--(D13:D38>0),D13:D38)^2/E38),"")) -> 1.4464978 | H38: =IF(AND(ISNUMBER(F38),ISNUMBER(G38)),F38-G38,"") -> -0.89299566 | I38: =IF(OR(NOT(ISNUMBER(F38)),NOT(ISNUMBER(G38))),"",IF(F38>G38,"A",IF(G38>F38,"B","HOLD"))) -> B | J38: =IF(I38="","",IF(I38="HOLD",0,IF(I38=I37,J37+1,1))) -> 10 | K38: =IF(I38="","",IF(J38>=Parameters!$B$5,I38,"HOLD")) -> B | L38: ='Actual Calc'!T38 -> 0 | M38: ='Actual Calc'!U38 -> 210692.45 | N38: =IF(OR(NOT(ISNUMBER(L38)),NOT(ISNUMBER(M38)),L38+M38=0),"",L38/(L38+M38)) -> 0 | O38: =IF(NOT(ISNUMBER(N38)),"",IF(K38="A",MIN(Parameters!$B$8,N38+Parameters!$B$6),IF(K38="B",MAX(Parameters!$B$7,N38-Parameters!$B$6),N38))) -> 0 | P38: =IF(NOT(ISNUMBER(O38)),"",MAX(0,L38-(L38+M38)*O38)) -> 0 | Q38: =IF(NOT(ISNUMBER(O38)),"",MAX(0,(L38+M38)*O38-L38)) -> 0 | R38: =IF(NOT(ISNUMBER(O38)),"",L38-P38+Q38) -> 0 | S38: =IF(NOT(ISNUMBER(O38)),"",M38+P38-Q38) -> 210692.45 | T38: =IF(OR(NOT(ISNUMBER(R38)),NOT(ISNUMBER(S38)),R38+S38=0),"",R38/(R38+S38)) -> 0 | U38: =IF(NOT(ISNUMBER(O38)),"",IF(P38>0.005,"Transfer "&TEXT(P38,"#,##0.00")&" A → B",IF(Q38>0.005,"Transfer "&TEXT(Q38,"#,##0.00")&" B → A","No transfer"))) -> No transfer | V38: Historical
A39: 43451 | B39: -0.004 | C39: -0.01922 | D39: =IF(AND(ISNUMBER(B39),ISNUMBER(C39)),(B39+C39)/2,"") -> -0.01161 | E39: =IF(NOT(ISNUMBER(D39)),"",COUNTIF(D14:D39,">0")) -> 11 | F39: =IF(OR(NOT(ISNUMBER(E39)),E39<2),"",IFERROR((SUMPRODUCT(--(D14:D39>0),B14:B39,D14:D39)-SUMPRODUCT(--(D14:D39>0),B14:B39)*SUMPRODUCT(--(D14:D39>0),D14:D39)/E39)/(SUMPRODUCT(--(D14:D39>0),D14:D39,D14:D39)-SUMPRODUCT(--(D14:D39>0),D14:D39)^2/E39),"")) -> 0.55350217 | G39: =IF(OR(NOT(ISNUMBER(E39)),E39<2),"",IFERROR((SUMPRODUCT(--(D14:D39>0),C14:C39,D14:D39)-SUMPRODUCT(--(D14:D39>0),C14:C39)*SUMPRODUCT(--(D14:D39>0),D14:D39)/E39)/(SUMPRODUCT(--(D14:D39>0),D14:D39,D14:D39)-SUMPRODUCT(--(D14:D39>0),D14:D39)^2/E39),"")) -> 1.4464978 | H39: =IF(AND(ISNUMBER(F39),ISNUMBER(G39)),F39-G39,"") -> -0.89299566 | I39: =IF(OR(NOT(ISNUMBER(F39)),NOT(ISNUMBER(G39))),"",IF(F39>G39,"A",IF(G39>F39,"B","HOLD"))) -> B | J39: =IF(I39="","",IF(I39="HOLD",0,IF(I39=I38,J38+1,1))) -> 11 | K39: =IF(I39="","",IF(J39>=Parameters!$B$5,I39,"HOLD")) -> B | L39: ='Actual Calc'!T39 -> 0 | M39: ='Actual Calc'!U39 -> 156716.92 | N39: =IF(OR(NOT(ISNUMBER(L39)),NOT(ISNUMBER(M39)),L39+M39=0),"",L39/(L39+M39)) -> 0 | O39: =IF(NOT(ISNUMBER(N39)),"",IF(K39="A",MIN(Parameters!$B$8,N39+Parameters!$B$6),IF(K39="B",MAX(Parameters!$B$7,N39-Parameters!$B$6),N39))) -> 0 | P39: =IF(NOT(ISNUMBER(O39)),"",MAX(0,L39-(L39+M39)*O39)) -> 0 | Q39: =IF(NOT(ISNUMBER(O39)),"",MAX(0,(L39+M39)*O39-L39)) -> 0 | R39: =IF(NOT(ISNUMBER(O39)),"",L39-P39+Q39) -> 0 | S39: =IF(NOT(ISNUMBER(O39)),"",M39+P39-Q39) -> 156716.92 | T39: =IF(OR(NOT(ISNUMBER(R39)),NOT(ISNUMBER(S39)),R39+S39=0),"",R39/(R39+S39)) -> 0 | U39: =IF(NOT(ISNUMBER(O39)),"",IF(P39>0.005,"Transfer "&TEXT(P39,"#,##0.00")&" A → B",IF(Q39>0.005,"Transfer "&TEXT(Q39,"#,##0.00")&" B → A","No transfer"))) -> No transfer | V39: Historical
A40: 43458 | B40: 0.04526 | C40: -0.00599 | D40: =IF(AND(ISNUMBER(B40),ISNUMBER(C40)),(B40+C40)/2,"") -> 0.019635 | E40: =IF(NOT(ISNUMBER(D40)),"",COUNTIF(D15:D40,">0")) -> 12 | F40: =IF(OR(NOT(ISNUMBER(E40)),E40<2),"",IFERROR((SUMPRODUCT(--(D15:D40>0),B15:B40,D15:D40)-SUMPRODUCT(--(D15:D40>0),B15:B40)*SUMPRODUCT(--(D15:D40>0),D15:D40)/E40)/(SUMPRODUCT(--(D15:D40>0),D15:D40,D15:D40)-SUMPRODUCT(--(D15:D40>0),D15:D40)^2/E40),"")) -> 1.3127656 | G40: =IF(OR(NOT(ISNUMBER(E40)),E40<2),"",IFERROR((SUMPRODUCT(--(D15:D40>0),C15:C40,D15:D40)-SUMPRODUCT(--(D15:D40>0),C15:C40)*SUMPRODUCT(--(D15:D40>0),D15:D40)/E40)/(SUMPRODUCT(--(D15:D40>0),D15:D40,D15:D40)-SUMPRODUCT(--(D15:D40>0),D15:D40)^2/E40),"")) -> 0.68723438 | H40: =IF(AND(ISNUMBER(F40),ISNUMBER(G40)),F40-G40,"") -> 0.62553123 | I40: =IF(OR(NOT(ISNUMBER(F40)),NOT(ISNUMBER(G40))),"",IF(F40>G40,"A",IF(G40>F40,"B","HOLD"))) -> A | J40: =IF(I40="","",IF(I40="HOLD",0,IF(I40=I39,J39+1,1))) -> 1 | K40: =IF(I40="","",IF(J40>=Parameters!$B$5,I40,"HOLD")) -> HOLD | L40: ='Actual Calc'!T40 -> 0 | M40: ='Actual Calc'!U40 -> 144207.4 | N40: =IF(OR(NOT(ISNUMBER(L40)),NOT(ISNUMBER(M40)),L40+M40=0),"",L40/(L40+M40)) -> 0 | O40: =IF(NOT(ISNUMBER(N40)),"",IF(K40="A",MIN(Parameters!$B$8,N40+Parameters!$B$6),IF(K40="B",MAX(Parameters!$B$7,N40-Parameters!$B$6),N40))) -> 0 | P40: =IF(NOT(ISNUMBER(O40)),"",MAX(0,L40-(L40+M40)*O40)) -> 0 | Q40: =IF(NOT(ISNUMBER(O40)),"",MAX(0,(L40+M40)*O40-L40)) -> 0 | R40: =IF(NOT(ISNUMBER(O40)),"",L40-P40+Q40) -> 0 | S40: =IF(NOT(ISNUMBER(O40)),"",M40+P40-Q40) -> 144207.4 | T40: =IF(OR(NOT(ISNUMBER(R40)),NOT(ISNUMBER(S40)),R40+S40=0),"",R40/(R40+S40)) -> 0 | U40: =IF(NOT(ISNUMBER(O40)),"",IF(P40>0.005,"Transfer "&TEXT(P40,"#,##0.00")&" A → B",IF(Q40>0.005,"Transfer "&TEXT(Q40,"#,##0.00")&" B → A","No transfer"))) -> No transfer | V40: Historical
... A437: 46237 | B437: 0.01614 | C437: 0 | D437: =IF(AND(ISNUMBER(B437),ISNUMBER(C437)),(B437+C437)/2,"") -> 0.00807 | E437: =IF(NOT(ISNUMBER(D437)),"",COUNTIF(D412:D437,">0")) -> 12 | F437: =IF(OR(NOT(ISNUMBER(E437)),E437<2),"",IFERROR((SUMPRODUCT(--(D412:D437>0),B412:B437,D412:D437)-SUMPRODUCT(--(D412:D437>0),B412:B437)*SUMPRODUCT(--(D412:D437>0),D412:D437)/E437)/(SUMPRODUCT(--(D412:D437>0),D412:D437,D412:D437)-SUMPRODUCT(--(D412:D437>0),D412:D437)^2/E437),"")) -> 0.9589331 | G437: =IF(OR(NOT(ISNUMBER(E437)),E437<2),"",IFERROR((SUMPRODUCT(--(D412:D437>0),C412:C437,D412:D437)-SUMPRODUCT(--(D412:D437>0),C412:C437)*SUMPRODUCT(--(D412:D437>0),D412:D437)/E437)/(SUMPRODUCT(--(D412:D437>0),D412:D437,D412:D437)-SUMPRODUCT(--(D412:D437>0),D412:D437)^2/E437),"")) -> 1.0410669 | H437: =IF(AND(ISNUMBER(F437),ISNUMBER(G437)),F437-G437,"") -> -0.082133808 | I437: =IF(OR(NOT(ISNUMBER(F437)),NOT(ISNUMBER(G437))),"",IF(F437>G437,"A",IF(G437>F437,"B","HOLD"))) -> B | J437: =IF(I437="","",IF(I437="HOLD",0,IF(I437=I436,J436+1,1))) -> 1 | K437: =IF(I437="","",IF(J437>=Parameters!$B$5,I437,"HOLD")) -> HOLD | L437: ='Actual Calc'!T437 -> 0 | M437: ='Actual Calc'!U437 -> 9.7571538e+13 | N437: =IF(OR(NOT(ISNUMBER(L437)),NOT(ISNUMBER(M437)),L437+M437=0),"",L437/(L437+M437)) -> 0 | O437: =IF(NOT(ISNUMBER(N437)),"",IF(K437="A",MIN(Parameters!$B$8,N437+Parameters!$B$6),IF(K437="B",MAX(Parameters!$B$7,N437-Parameters!$B$6),N437))) -> 0 | P437: =IF(NOT(ISNUMBER(O437)),"",MAX(0,L437-(L437+M437)*O437)) -> 0 | Q437: =IF(NOT(ISNUMBER(O437)),"",MAX(0,(L437+M437)*O437-L437)) -> 0 | R437: =IF(NOT(ISNUMBER(O437)),"",L437-P437+Q437) -> 0 | S437: =IF(NOT(ISNUMBER(O437)),"",M437+P437-Q437) -> 9.7571538e+13 | T437: =IF(OR(NOT(ISNUMBER(R437)),NOT(ISNUMBER(S437)),R437+S437=0),"",R437/(R437+S437)) -> 0 | U437: =IF(NOT(ISNUMBER(O437)),"",IF(P437>0.005,"Transfer "&TEXT(P437,"#,##0.00")&" A → B",IF(Q437>0.005,"Transfer "&TEXT(Q437,"#,##0.00")&" B → A","No transfer"))) -> No transfer | V437: Historical | B SKIP
A438: 46244 | B438: -0.004 | C438: -0.004 | D438: =IF(AND(ISNUMBER(B438),ISNUMBER(C438)),(B438+C438)/2,"") -> -0.004 | E438: =IF(NOT(ISNUMBER(D438)),"",COUNTIF(D413:D438,">0")) -> 11 | F438: =IF(OR(NOT(ISNUMBER(E438)),E438<2),"",IFERROR((SUMPRODUCT(--(D413:D438>0),B413:B438,D413:D438)-SUMPRODUCT(--(D413:D438>0),B413:B438)*SUMPRODUCT(--(D413:D438>0),D413:D438)/E438)/(SUMPRODUCT(--(D413:D438>0),D413:D438,D413:D438)-SUMPRODUCT(--(D413:D438>0),D413:D438)^2/E438),"")) -> 0.95483386 | G438: =IF(OR(NOT(ISNUMBER(E438)),E438<2),"",IFERROR((SUMPRODUCT(--(D413:D438>0),C413:C438,D413:D438)-SUMPRODUCT(--(D413:D438>0),C413:C438)*SUMPRODUCT(--(D413:D438>0),D413:D438)/E438)/(SUMPRODUCT(--(D413:D438>0),D413:D438,D413:D438)-SUMPRODUCT(--(D413:D438>0),D413:D438)^2/E438),"")) -> 1.0451661 | H438: =IF(AND(ISNUMBER(F438),ISNUMBER(G438)),F438-G438,"") -> -0.090332285 | I438: =IF(OR(NOT(ISNUMBER(F438)),NOT(ISNUMBER(G438))),"",IF(F438>G438,"A",IF(G438>F438,"B","HOLD"))) -> B | J438: =IF(I438="","",IF(I438="HOLD",0,IF(I438=I437,J437+1,1))) -> 2 | K438: =IF(I438="","",IF(J438>=Parameters!$B$5,I438,"HOLD")) -> HOLD | N438: =IF(OR(NOT(ISNUMBER(L438)),NOT(ISNUMBER(M438)),L438+M438=0),"",L438/(L438+M438)) | O438: =IF(NOT(ISNUMBER(N438)),"",IF(K438="A",MIN(Parameters!$B$8,N438+Parameters!$B$6),IF(K438="B",MAX(Parameters!$B$7,N438-Parameters!$B$6),N438))) | P438: =IF(NOT(ISNUMBER(O438)),"",MAX(0,L438-(L438+M438)*O438)) | Q438: =IF(NOT(ISNUMBER(O438)),"",MAX(0,(L438+M438)*O438-L438)) | R438: =IF(NOT(ISNUMBER(O438)),"",L438-P438+Q438) | S438: =IF(NOT(ISNUMBER(O438)),"",M438+P438-Q438) | T438: =IF(OR(NOT(ISNUMBER(R438)),NOT(ISNUMBER(S438)),R438+S438=0),"",R438/(R438+S438)) -> #VALUE! | U438: =IF(NOT(ISNUMBER(O438)),"",IF(P438>0.005,"Transfer "&TEXT(P438,"#,##0.00")&" A → B",IF(Q438>0.005,"Transfer "&TEXT(Q438,"#,##0.00")&" B → A","No transfer"))) | V438: Future manual input
A439: 46251 | D439: =IF(AND(ISNUMBER(B439),ISNUMBER(C439)),(B439+C439)/2,"") | E439: =IF(NOT(ISNUMBER(D439)),"",COUNTIF(D414:D439,">0")) | F439: =IF(OR(NOT(ISNUMBER(E439)),E439<2),"",IFERROR((SUMPRODUCT(--(D414:D439>0),B414:B439,D414:D439)-SUMPRODUCT(--(D414:D439>0),B414:B439)*SUMPRODUCT(--(D414:D439>0),D414:D439)/E439)/(SUMPRODUCT(--(D414:D439>0),D414:D439,D414:D439)-SUMPRODUCT(--(D414:D439>0),D414:D439)^2/E439),"")) | G439: =IF(OR(NOT(ISNUMBER(E439)),E439<2),"",IFERROR((SUMPRODUCT(--(D414:D439>0),C414:C439,D414:D439)-SUMPRODUCT(--(D414:D439>0),C414:C439)*SUMPRODUCT(--(D414:D439>0),D414:D439)/E439)/(SUMPRODUCT(--(D414:D439>0),D414:D439,D414:D439)-SUMPRODUCT(--(D414:D439>0),D414:D439)^2/E439),"")) | H439: =IF(AND(ISNUMBER(F439),ISNUMBER(G439)),F439-G439,"") | I439: =IF(OR(NOT(ISNUMBER(F439)),NOT(ISNUMBER(G439))),"",IF(F439>G439,"A",IF(G439>F439,"B","HOLD"))) | J439: =IF(I439="","",IF(I439="HOLD",0,IF(I439=I438,J438+1,1))) | K439: =IF(I439="","",IF(J439>=Parameters!$B$5,I439,"HOLD")) | N439: =IF(OR(NOT(ISNUMBER(L439)),NOT(ISNUMBER(M439)),L439+M439=0),"",L439/(L439+M439)) | O439: =IF(NOT(ISNUMBER(N439)),"",IF(K439="A",MIN(Parameters!$B$8,N439+Parameters!$B$6),IF(K439="B",MAX(Parameters!$B$7,N439-Parameters!$B$6),N439))) | P439: =IF(NOT(ISNUMBER(O439)),"",MAX(0,L439-(L439+M439)*O439)) | Q439: =IF(NOT(ISNUMBER(O439)),"",MAX(0,(L439+M439)*O439-L439)) | R439: =IF(NOT(ISNUMBER(O439)),"",L439-P439+Q439) | S439: =IF(NOT(ISNUMBER(O439)),"",M439+P439-Q439) | T439: =IF(OR(NOT(ISNUMBER(R439)),NOT(ISNUMBER(S439)),R439+S439=0),"",R439/(R439+S439)) -> #VALUE! | U439: =IF(NOT(ISNUMBER(O439)),"",IF(P439>0.005,"Transfer "&TEXT(P439,"#,##0.00")&" A → B",IF(Q439>0.005,"Transfer "&TEXT(Q439,"#,##0.00")&" B → A","No transfer"))) | V439: Future manual input
A440: 46258 | D440: =IF(AND(ISNUMBER(B440),ISNUMBER(C440)),(B440+C440)/2,"") | E440: =IF(NOT(ISNUMBER(D440)),"",COUNTIF(D415:D440,">0")) | F440: =IF(OR(NOT(ISNUMBER(E440)),E440<2),"",IFERROR((SUMPRODUCT(--(D415:D440>0),B415:B440,D415:D440)-SUMPRODUCT(--(D415:D440>0),B415:B440)*SUMPRODUCT(--(D415:D440>0),D415:D440)/E440)/(SUMPRODUCT(--(D415:D440>0),D415:D440,D415:D440)-SUMPRODUCT(--(D415:D440>0),D415:D440)^2/E440),"")) | G440: =IF(OR(NOT(ISNUMBER(E440)),E440<2),"",IFERROR((SUMPRODUCT(--(D415:D440>0),C415:C440,D415:D440)-SUMPRODUCT(--(D415:D440>0),C415:C440)*SUMPRODUCT(--(D415:D440>0),D415:D440)/E440)/(SUMPRODUCT(--(D415:D440>0),D415:D440,D415:D440)-SUMPRODUCT(--(D415:D440>0),D415:D440)^2/E440),"")) | H440: =IF(AND(ISNUMBER(F440),ISNUMBER(G440)),F440-G440,"") | I440: =IF(OR(NOT(ISNUMBER(F440)),NOT(ISNUMBER(G440))),"",IF(F440>G440,"A",IF(G440>F440,"B","HOLD"))) | J440: =IF(I440="","",IF(I440="HOLD",0,IF(I440=I439,J439+1,1))) | K440: =IF(I440="","",IF(J440>=Parameters!$B$5,I440,"HOLD")) | N440: =IF(OR(NOT(ISNUMBER(L440)),NOT(ISNUMBER(M440)),L440+M440=0),"",L440/(L440+M440)) | O440: =IF(NOT(ISNUMBER(N440)),"",IF(K440="A",MIN(Parameters!$B$8,N440+Parameters!$B$6),IF(K440="B",MAX(Parameters!$B$7,N440-Parameters!$B$6),N440))) | P440: =IF(NOT(ISNUMBER(O440)),"",MAX(0,L440-(L440+M440)*O440)) | Q440: =IF(NOT(ISNUMBER(O440)),"",MAX(0,(L440+M440)*O440-L440)) | R440: =IF(NOT(ISNUMBER(O440)),"",L440-P440+Q440) | S440: =IF(NOT(ISNUMBER(O440)),"",M440+P440-Q440) | T440: =IF(OR(NOT(ISNUMBER(R440)),NOT(ISNUMBER(S440)),R440+S440=0),"",R440/(R440+S440)) -> #VALUE! | U440: =IF(NOT(ISNUMBER(O440)),"",IF(P440>0.005,"Transfer "&TEXT(P440,"#,##0.00")&" A → B",IF(Q440>0.005,"Transfer "&TEXT(Q440,"#,##0.00")&" B → A","No transfer"))) | V440: Future manual input
A441: 46265 | D441: =IF(AND(ISNUMBER(B441),ISNUMBER(C441)),(B441+C441)/2,"") | E441: =IF(NOT(ISNUMBER(D441)),"",COUNTIF(D416:D441,">0")) | F441: =IF(OR(NOT(ISNUMBER(E441)),E441<2),"",IFERROR((SUMPRODUCT(--(D416:D441>0),B416:B441,D416:D441)-SUMPRODUCT(--(D416:D441>0),B416:B441)*SUMPRODUCT(--(D416:D441>0),D416:D441)/E441)/(SUMPRODUCT(--(D416:D441>0),D416:D441,D416:D441)-SUMPRODUCT(--(D416:D441>0),D416:D441)^2/E441),"")) | G441: =IF(OR(NOT(ISNUMBER(E441)),E441<2),"",IFERROR((SUMPRODUCT(--(D416:D441>0),C416:C441,D416:D441)-SUMPRODUCT(--(D416:D441>0),C416:C441)*SUMPRODUCT(--(D416:D441>0),D416:D441)/E441)/(SUMPRODUCT(--(D416:D441>0),D416:D441,D416:D441)-SUMPRODUCT(--(D416:D441>0),D416:D441)^2/E441),"")) | H441: =IF(AND(ISNUMBER(F441),ISNUMBER(G441)),F441-G441,"") | I441: =IF(OR(NOT(ISNUMBER(F441)),NOT(ISNUMBER(G441))),"",IF(F441>G441,"A",IF(G441>F441,"B","HOLD"))) | J441: =IF(I441="","",IF(I441="HOLD",0,IF(I441=I440,J440+1,1))) | K441: =IF(I441="","",IF(J441>=Parameters!$B$5,I441,"HOLD")) | N441: =IF(OR(NOT(ISNUMBER(L441)),NOT(ISNUMBER(M441)),L441+M441=0),"",L441/(L441+M441)) | O441: =IF(NOT(ISNUMBER(N441)),"",IF(K441="A",MIN(Parameters!$B$8,N441+Parameters!$B$6),IF(K441="B",MAX(Parameters!$B$7,N441-Parameters!$B$6),N441))) | P441: =IF(NOT(ISNUMBER(O441)),"",MAX(0,L441-(L441+M441)*O441)) | Q441: =IF(NOT(ISNUMBER(O441)),"",MAX(0,(L441+M441)*O441-L441)) | R441: =IF(NOT(ISNUMBER(O441)),"",L441-P441+Q441) | S441: =IF(NOT(ISNUMBER(O441)),"",M441+P441-Q441) | T441: =IF(OR(NOT(ISNUMBER(R441)),NOT(ISNUMBER(S441)),R441+S441=0),"",R441/(R441+S441)) -> #VALUE! | U441: =IF(NOT(ISNUMBER(O441)),"",IF(P441>0.005,"Transfer "&TEXT(P441,"#,##0.00")&" A → B",IF(Q441>0.005,"Transfer "&TEXT(Q441,"#,##0.00")&" B → A","No transfer"))) | V441: Future manual input
A442: 46272 | D442: =IF(AND(ISNUMBER(B442),ISNUMBER(C442)),(B442+C442)/2,"") | E442: =IF(NOT(ISNUMBER(D442)),"",COUNTIF(D417:D442,">0")) | F442: =IF(OR(NOT(ISNUMBER(E442)),E442<2),"",IFERROR((SUMPRODUCT(--(D417:D442>0),B417:B442,D417:D442)-SUMPRODUCT(--(D417:D442>0),B417:B442)*SUMPRODUCT(--(D417:D442>0),D417:D442)/E442)/(SUMPRODUCT(--(D417:D442>0),D417:D442,D417:D442)-SUMPRODUCT(--(D417:D442>0),D417:D442)^2/E442),"")) | G442: =IF(OR(NOT(ISNUMBER(E442)),E442<2),"",IFERROR((SUMPRODUCT(--(D417:D442>0),C417:C442,D417:D442)-SUMPRODUCT(--(D417:D442>0),C417:C442)*SUMPRODUCT(--(D417:D442>0),D417:D442)/E442)/(SUMPRODUCT(--(D417:D442>0),D417:D442,D417:D442)-SUMPRODUCT(--(D417:D442>0),D417:D442)^2/E442),"")) | H442: =IF(AND(ISNUMBER(F442),ISNUMBER(G442)),F442-G442,"") | I442: =IF(OR(NOT(ISNUMBER(F442)),NOT(ISNUMBER(G442))),"",IF(F442>G442,"A",IF(G442>F442,"B","HOLD"))) | J442: =IF(I442="","",IF(I442="HOLD",0,IF(I442=I441,J441+1,1))) | K442: =IF(I442="","",IF(J442>=Parameters!$B$5,I442,"HOLD")) | N442: =IF(OR(NOT(ISNUMBER(L442)),NOT(ISNUMBER(M442)),L442+M442=0),"",L442/(L442+M442)) | O442: =IF(NOT(ISNUMBER(N442)),"",IF(K442="A",MIN(Parameters!$B$8,N442+Parameters!$B$6),IF(K442="B",MAX(Parameters!$B$7,N442-Parameters!$B$6),N442))) | P442: =IF(NOT(ISNUMBER(O442)),"",MAX(0,L442-(L442+M442)*O442)) | Q442: =IF(NOT(ISNUMBER(O442)),"",MAX(0,(L442+M442)*O442-L442)) | R442: =IF(NOT(ISNUMBER(O442)),"",L442-P442+Q442) | S442: =IF(NOT(ISNUMBER(O442)),"",M442+P442-Q442) | T442: =IF(OR(NOT(ISNUMBER(R442)),NOT(ISNUMBER(S442)),R442+S442=0),"",R442/(R442+S442)) -> #VALUE! | U442: =IF(NOT(ISNUMBER(O442)),"",IF(P442>0.005,"Transfer "&TEXT(P442,"#,##0.00")&" A → B",IF(Q442>0.005,"Transfer "&TEXT(Q442,"#,##0.00")&" B → A","No transfer"))) | V442: Future manual input
A443: 46279 | D443: =IF(AND(ISNUMBER(B443),ISNUMBER(C443)),(B443+C443)/2,"") | E443: =IF(NOT(ISNUMBER(D443)),"",COUNTIF(D418:D443,">0")) | F443: =IF(OR(NOT(ISNUMBER(E443)),E443<2),"",IFERROR((SUMPRODUCT(--(D418:D443>0),B418:B443,D418:D443)-SUMPRODUCT(--(D418:D443>0),B418:B443)*SUMPRODUCT(--(D418:D443>0),D418:D443)/E443)/(SUMPRODUCT(--(D418:D443>0),D418:D443,D418:D443)-SUMPRODUCT(--(D418:D443>0),D418:D443)^2/E443),"")) | G443: =IF(OR(NOT(ISNUMBER(E443)),E443<2),"",IFERROR((SUMPRODUCT(--(D418:D443>0),C418:C443,D418:D443)-SUMPRODUCT(--(D418:D443>0),C418:C443)*SUMPRODUCT(--(D418:D443>0),D418:D443)/E443)/(SUMPRODUCT(--(D418:D443>0),D418:D443,D418:D443)-SUMPRODUCT(--(D418:D443>0),D418:D443)^2/E443),"")) | H443: =IF(AND(ISNUMBER(F443),ISNUMBER(G443)),F443-G443,"") | I443: =IF(OR(NOT(ISNUMBER(F443)),NOT(ISNUMBER(G443))),"",IF(F443>G443,"A",IF(G443>F443,"B","HOLD"))) | J443: =IF(I443="","",IF(I443="HOLD",0,IF(I443=I442,J442+1,1))) | K443: =IF(I443="","",IF(J443>=Parameters!$B$5,I443,"HOLD")) | N443: =IF(OR(NOT(ISNUMBER(L443)),NOT(ISNUMBER(M443)),L443+M443=0),"",L443/(L443+M443)) | O443: =IF(NOT(ISNUMBER(N443)),"",IF(K443="A",MIN(Parameters!$B$8,N443+Parameters!$B$6),IF(K443="B",MAX(Parameters!$B$7,N443-Parameters!$B$6),N443))) | P443: =IF(NOT(ISNUMBER(O443)),"",MAX(0,L443-(L443+M443)*O443)) | Q443: =IF(NOT(ISNUMBER(O443)),"",MAX(0,(L443+M443)*O443-L443)) | R443: =IF(NOT(ISNUMBER(O443)),"",L443-P443+Q443) | S443: =IF(NOT(ISNUMBER(O443)),"",M443+P443-Q443) | T443: =IF(OR(NOT(ISNUMBER(R443)),NOT(ISNUMBER(S443)),R443+S443=0),"",R443/(R443+S443)) -> #VALUE! | U443: =IF(NOT(ISNUMBER(O443)),"",IF(P443>0.005,"Transfer "&TEXT(P443,"#,##0.00")&" A → B",IF(Q443>0.005,"Transfer "&TEXT(Q443,"#,##0.00")&" B → A","No transfer"))) | V443: Future manual input
A444: 46286 | D444: =IF(AND(ISNUMBER(B444),ISNUMBER(C444)),(B444+C444)/2,"") | E444: =IF(NOT(ISNUMBER(D444)),"",COUNTIF(D419:D444,">0")) | F444: =IF(OR(NOT(ISNUMBER(E444)),E444<2),"",IFERROR((SUMPRODUCT(--(D419:D444>0),B419:B444,D419:D444)-SUMPRODUCT(--(D419:D444>0),B419:B444)*SUMPRODUCT(--(D419:D444>0),D419:D444)/E444)/(SUMPRODUCT(--(D419:D444>0),D419:D444,D419:D444)-SUMPRODUCT(--(D419:D444>0),D419:D444)^2/E444),"")) | G444: =IF(OR(NOT(ISNUMBER(E444)),E444<2),"",IFERROR((SUMPRODUCT(--(D419:D444>0),C419:C444,D419:D444)-SUMPRODUCT(--(D419:D444>0),C419:C444)*SUMPRODUCT(--(D419:D444>0),D419:D444)/E444)/(SUMPRODUCT(--(D419:D444>0),D419:D444,D419:D444)-SUMPRODUCT(--(D419:D444>0),D419:D444)^2/E444),"")) | H444: =IF(AND(ISNUMBER(F444),ISNUMBER(G444)),F444-G444,"") | I444: =IF(OR(NOT(ISNUMBER(F444)),NOT(ISNUMBER(G444))),"",IF(F444>G444,"A",IF(G444>F444,"B","HOLD"))) | J444: =IF(I444="","",IF(I444="HOLD",0,IF(I444=I443,J443+1,1))) | K444: =IF(I444="","",IF(J444>=Parameters!$B$5,I444,"HOLD")) | N444: =IF(OR(NOT(ISNUMBER(L444)),NOT(ISNUMBER(M444)),L444+M444=0),"",L444/(L444+M444)) | O444: =IF(NOT(ISNUMBER(N444)),"",IF(K444="A",MIN(Parameters!$B$8,N444+Parameters!$B$6),IF(K444="B",MAX(Parameters!$B$7,N444-Parameters!$B$6),N444))) | P444: =IF(NOT(ISNUMBER(O444)),"",MAX(0,L444-(L444+M444)*O444)) | Q444: =IF(NOT(ISNUMBER(O444)),"",MAX(0,(L444+M444)*O444-L444)) | R444: =IF(NOT(ISNUMBER(O444)),"",L444-P444+Q444) | S444: =IF(NOT(ISNUMBER(O444)),"",M444+P444-Q444) | T444: =IF(OR(NOT(ISNUMBER(R444)),NOT(ISNUMBER(S444)),R444+S444=0),"",R444/(R444+S444)) -> #VALUE! | U444: =IF(NOT(ISNUMBER(O444)),"",IF(P444>0.005,"Transfer "&TEXT(P444,"#,##0.00")&" A → B",IF(Q444>0.005,"Transfer "&TEXT(Q444,"#,##0.00")&" B → A","No transfer"))) | V444: Future manual input
