Workbook

Sheet Summary
A1: OPPW baseline versus loss-control rule | B1: OPPW baseline versus loss-control rule | C1: OPPW baseline versus loss-control rule | D1: OPPW baseline versus loss-control rule | E1: OPPW baseline versus loss-control rule | F1: OPPW baseline versus loss-control rule | G1: OPPW baseline versus loss-control rule | H1: OPPW baseline versus loss-control rule | I1: OPPW baseline versus loss-control rule | J1: OPPW baseline versus loss-control rule | K1: OPPW baseline versus loss-control rule | L1: OPPW baseline versus loss-control rule
A2: OPPW baseline versus loss-control rule | B2: OPPW baseline versus loss-control rule | C2: OPPW baseline versus loss-control rule | D2: OPPW baseline versus loss-control rule | E2: OPPW baseline versus loss-control rule | F2: OPPW baseline versus loss-control rule | G2: OPPW baseline versus loss-control rule | H2: OPPW baseline versus loss-control rule | I2: OPPW baseline versus loss-control rule | J2: OPPW baseline versus loss-control rule | K2: OPPW baseline versus loss-control rule | L2: OPPW baseline versus loss-control rule
A3: Stateful comparison at 11.3x leverage with a two-outcome damage gate and no premarket-low rule. Tuesday re-entry is an approximate repricing overlay normalized from Friday. | B3: Stateful comparison at 11.3x leverage. Tuesday re-entry is an approximate repricing overlay normalized from Friday. | C3: Stateful comparison at 11.3x leverage. Tuesday re-entry is an approximate repricing overlay normalized from Friday. | D3: Stateful comparison at 11.3x leverage. Tuesday re-entry is an approximate repricing overlay normalized from Friday. | E3: Stateful comparison at 11.3x leverage. Tuesday re-entry is an approximate repricing overlay normalized from Friday. | F3: Stateful comparison at 11.3x leverage. Tuesday re-entry is an approximate repricing overlay normalized from Friday. | G3: Stateful comparison at 11.3x leverage. Tuesday re-entry is an approximate repricing overlay normalized from Friday. | H3: Stateful comparison at 11.3x leverage. Tuesday re-entry is an approximate repricing overlay normalized from Friday. | I3: Stateful comparison at 11.3x leverage. Tuesday re-entry is an approximate repricing overlay normalized from Friday. | J3: Stateful comparison at 11.3x leverage. Tuesday re-entry is an approximate repricing overlay normalized from Friday. | K3: Stateful comparison at 11.3x leverage. Tuesday re-entry is an approximate repricing overlay normalized from Friday. | L3: Stateful comparison at 11.3x leverage. Tuesday re-entry is an approximate repricing overlay normalized from Friday.
N4: Week | O4: Baseline log10 equity multiple | P4: Rule log10 equity multiple
A5: Trades | D5: Changed | G5: Model status | N5: =TEXT('All Trades'!B5,"yyyy-mm-dd") -> yyyy-04-16 | O5: =LOG10('All Trades'!X5/Assumptions!$B$11) -> 0.095321415 | P5: =LOG10('All Trades'!AA5/Assumptions!$B$11) -> 0.095321415
A6: =COUNT('All Trades'!$A$5:$A$436) -> 432 | D6: =COUNTIF('All Trades'!$S$5:$S$436,"<>BASELINE") -> 57 | G6: =IF(COUNTIF(Checks!$F$5:$F$11,"CHECK")=0,"OK","CHECK") -> OK | N6: =TEXT('All Trades'!B6,"yyyy-mm-dd") -> yyyy-04-23 | O6: =LOG10('All Trades'!X6/Assumptions!$B$11) -> 0.0026182747 | P6: =LOG10('All Trades'!AA6/Assumptions!$B$11) -> 0.0026182747
N7: =TEXT('All Trades'!B7,"yyyy-mm-dd") -> yyyy-04-30 | O7: =LOG10('All Trades'!X7/Assumptions!$B$11) -> -0.028241295 | P7: =LOG10('All Trades'!AA7/Assumptions!$B$11) -> -0.028241295
A8: Baseline weekly geo | D8: Rule weekly geo | G8: Weekly uplift | N8: =TEXT('All Trades'!B8,"yyyy-mm-dd") -> yyyy-05-07 | O8: =LOG10('All Trades'!X8/Assumptions!$B$11) -> 0.071549114 | P8: =LOG10('All Trades'!AA8/Assumptions!$B$11) -> -0.028241295
A9: =POWER('All Trades'!X436/Assumptions!$B$11,1/COUNT('All Trades'!$A$5:$A$436))-1 -> 0.033235232 | D9: =POWER('All Trades'!AA436/Assumptions!$B$11,1/COUNT('All Trades'!$A$5:$A$436))-1 -> 0.042811919 | G9: =D9-A9 -> 0.0095766862 | N9: =TEXT('All Trades'!B9,"yyyy-mm-dd") -> yyyy-05-14 | O9: =LOG10('All Trades'!X9/Assumptions!$B$11) -> 0.051461524 | P9: =LOG10('All Trades'!AA9/Assumptions!$B$11) -> -0.048328885
N10: =TEXT('All Trades'!B10,"yyyy-mm-dd") -> yyyy-05-21 | O10: =LOG10('All Trades'!X10/Assumptions!$B$11) -> 0.031373935 | P10: =LOG10('All Trades'!AA10/Assumptions!$B$11) -> -0.068416475
A11: Baseline max DD | D11: Rule max DD | G11: Target rule raw | N11: =TEXT('All Trades'!B11,"yyyy-mm-dd") -> yyyy-05-29 | O11: =LOG10('All Trades'!X11/Assumptions!$B$11) -> 0.13030548 | P11: =LOG10('All Trades'!AA11/Assumptions!$B$11) -> 0.030515071
A12: =-MIN('All Trades'!Z5:Z436) -> 0.96825298 | D12: =-MIN('All Trades'!AC5:AC436) -> 0.70586893 | G12: ='All Trades'!T435 -> 0 | N12: =TEXT('All Trades'!B12,"yyyy-mm-dd") -> yyyy-06-04 | O12: =LOG10('All Trades'!X12/Assumptions!$B$11) -> 0.1655899 | P12: =LOG10('All Trades'!AA12/Assumptions!$B$11) -> 0.065799486
N13: =TEXT('All Trades'!B13,"yyyy-mm-dd") -> yyyy-06-11 | O13: =LOG10('All Trades'!X13/Assumptions!$B$11) -> 0.23610061 | P13: =LOG10('All Trades'!AA13/Assumptions!$B$11) -> 0.1363102
N14: =TEXT('All Trades'!B14,"yyyy-mm-dd") -> yyyy-06-18 | O14: =LOG10('All Trades'!X14/Assumptions!$B$11) -> 0.21601302 | P14: =LOG10('All Trades'!AA14/Assumptions!$B$11) -> 0.11622261
A15: Period | B15: Weeks | C15: Baseline weekly geo | D15: Rule weekly geo | E15: Difference | F15: Baseline CAGR | G15: Rule CAGR | N15: =TEXT('All Trades'!B15,"yyyy-mm-dd") -> yyyy-06-25 | O15: =LOG10('All Trades'!X15/Assumptions!$B$11) -> 0.19592543 | P15: =LOG10('All Trades'!AA15/Assumptions!$B$11) -> 0.09613502
A16: Full history | B16: =432 -> 432 | C16: =POWER('All Trades'!X436/Assumptions!$B$11,1/B16)-1 -> 0.033235232 | D16: =POWER('All Trades'!AA436/Assumptions!$B$11,1/B16)-1 -> 0.042811919 | E16: =D16-C16 -> 0.0095766862 | F16: =POWER(1+C16,52)-1 -> 4.4746802 | G16: =POWER(1+D16,52)-1 -> 7.8452738 | N16: =TEXT('All Trades'!B16,"yyyy-mm-dd") -> yyyy-07-02 | O16: =LOG10('All Trades'!X16/Assumptions!$B$11) -> 0.27038164 | P16: =LOG10('All Trades'!AA16/Assumptions!$B$11) -> 0.17059123
A17: 2018-2020 | B17: =140 -> 140 | C17: =POWER('All Trades'!X144/Assumptions!$B$11,1/B17)-1 -> 0.034410083 | D17: =POWER('All Trades'!AA144/Assumptions!$B$11,1/B17)-1 -> 0.044221429 | E17: =D17-C17 -> 0.0098113465 | F17: =POWER(1+C17,52)-1 -> 4.8079484 | G17: =POWER(1+D17,52)-1 -> 8.488887 | N17: =TEXT('All Trades'!B17,"yyyy-mm-dd") -> yyyy-07-09 | O17: =LOG10('All Trades'!X17/Assumptions!$B$11) -> 0.34887072 | P17: =LOG10('All Trades'!AA17/Assumptions!$B$11) -> 0.24908031
A18: 2021 | B18: =52 -> 52 | C18: =POWER('All Trades'!X196/'All Trades'!X144,1/B18)-1 -> 0.007783789 | D18: =POWER('All Trades'!AA196/'All Trades'!AA144,1/B18)-1 -> 0.016932448 | E18: =D18-C18 -> 0.0091486589 | F18: =POWER(1+C18,52)-1 -> 0.49659104 | G18: =POWER(1+D18,52)-1 -> 1.39436 | N18: =TEXT('All Trades'!B18,"yyyy-mm-dd") -> yyyy-07-16 | O18: =LOG10('All Trades'!X18/Assumptions!$B$11) -> 0.32878313 | P18: =LOG10('All Trades'!AA18/Assumptions!$B$11) -> 0.22899272
A19: 2022-2025 | B19: =209 -> 209 | C19: =POWER('All Trades'!X405/'All Trades'!X196,1/B19)-1 -> 0.040392243 | D19: =POWER('All Trades'!AA405/'All Trades'!AA196,1/B19)-1 -> 0.04458887 | E19: =D19-C19 -> 0.004196627 | F19: =POWER(1+C19,52)-1 -> 6.8387983 | G19: =POWER(1+D19,52)-1 -> 8.6640797 | N19: =TEXT('All Trades'!B19,"yyyy-mm-dd") -> yyyy-07-23 | O19: =LOG10('All Trades'!X19/Assumptions!$B$11) -> 0.379316 | P19: =LOG10('All Trades'!AA19/Assumptions!$B$11) -> 0.27952559
A20: 2026 | B20: =31 -> 31 | C20: =POWER('All Trades'!X436/'All Trades'!X405,1/B20)-1 -> 0.023123876 | D20: =POWER('All Trades'!AA436/'All Trades'!AA405,1/B20)-1 -> 0.06875675 | E20: =D20-C20 -> 0.045632874 | F20: =POWER(1+C20,52)-1 -> 2.2829738 | G20: =POWER(1+D20,52)-1 -> 30.746896 | N20: =TEXT('All Trades'!B20,"yyyy-mm-dd") -> yyyy-07-30 | O20: =LOG10('All Trades'!X20/Assumptions!$B$11) -> 0.37079194 | P20: =LOG10('All Trades'!AA20/Assumptions!$B$11) -> 0.27100154
N21: =TEXT('All Trades'!B21,"yyyy-mm-dd") -> yyyy-08-06 | O21: =LOG10('All Trades'!X21/Assumptions!$B$11) -> 0.38512806 | P21: =LOG10('All Trades'!AA21/Assumptions!$B$11) -> 0.28533765
N22: =TEXT('All Trades'!B22,"yyyy-mm-dd") -> yyyy-08-13 | O22: =LOG10('All Trades'!X22/Assumptions!$B$11) -> 0.34827341 | P22: =LOG10('All Trades'!AA22/Assumptions!$B$11) -> 0.248483
A23: Rule action | B23: Trades | N23: =TEXT('All Trades'!B23,"yyyy-mm-dd") -> yyyy-08-20 | O23: =LOG10('All Trades'!X23/Assumptions!$B$11) -> 0.40522397 | P23: =LOG10('All Trades'!AA23/Assumptions!$B$11) -> 0.30543357
A24: BASELINE | B24: =COUNTIF('All Trades'!$S$5:$S$436,"BASELINE") -> 375 | N24: =TEXT('All Trades'!B24,"yyyy-mm-dd") -> yyyy-08-27 | O24: =LOG10('All Trades'!X24/Assumptions!$B$11) -> 0.48297513 | P24: =LOG10('All Trades'!AA24/Assumptions!$B$11) -> 0.38318472
A25: DAMAGE SKIP | B25: =COUNTIF('All Trades'!$S$5:$S$436,"DAMAGE SKIP") -> 35 | N25: =TEXT('All Trades'!B25,"yyyy-mm-dd") -> yyyy-09-04 | O25: =LOG10('All Trades'!X25/Assumptions!$B$11) -> 0.41033573 | P25: =LOG10('All Trades'!AA25/Assumptions!$B$11) -> 0.31054533
A26: GAP/MOM SKIP | B26: =COUNTIF('All Trades'!$S$5:$S$436,"GAP/MOM SKIP") -> 19 | N26: =TEXT('All Trades'!B26,"yyyy-mm-dd") -> yyyy-09-10 | O26: =LOG10('All Trades'!X26/Assumptions!$B$11) -> 0.46047527 | P26: =LOG10('All Trades'!AA26/Assumptions!$B$11) -> 0.36068486
A27: TUESDAY RE-ENTRY | B27: =COUNTIF('All Trades'!$S$5:$S$436,"TUESDAY RE-ENTRY") -> 3 | N27: =TEXT('All Trades'!B27,"yyyy-mm-dd") -> yyyy-09-17 | O27: =LOG10('All Trades'!X27/Assumptions!$B$11) -> 0.44054185 | P27: =LOG10('All Trades'!AA27/Assumptions!$B$11) -> 0.34075144
N28: =TEXT('All Trades'!B28,"yyyy-mm-dd") -> yyyy-09-24 | O28: =LOG10('All Trades'!X28/Assumptions!$B$11) -> 0.49085624 | P28: =LOG10('All Trades'!AA28/Assumptions!$B$11) -> 0.39106583
N29: =TEXT('All Trades'!B29,"yyyy-mm-dd") -> yyyy-10-01 | O29: =LOG10('All Trades'!X29/Assumptions!$B$11) -> 0.47179541 | P29: =LOG10('All Trades'!AA29/Assumptions!$B$11) -> 0.372005
N30: =TEXT('All Trades'!B30,"yyyy-mm-dd") -> yyyy-10-08 | O30: =LOG10('All Trades'!X30/Assumptions!$B$11) -> 0.099548267 | P30: =LOG10('All Trades'!AA30/Assumptions!$B$11) -> -0.00024214235
N31: =TEXT('All Trades'!B31,"yyyy-mm-dd") -> yyyy-10-15 | O31: =LOG10('All Trades'!X31/Assumptions!$B$11) -> 0.079460677 | P31: =LOG10('All Trades'!AA31/Assumptions!$B$11) -> -0.00024214235
N32: =TEXT('All Trades'!B32,"yyyy-mm-dd") -> yyyy-10-22 | O32: =LOG10('All Trades'!X32/Assumptions!$B$11) -> 0.063516536 | P32: =LOG10('All Trades'!AA32/Assumptions!$B$11) -> -0.00024214235
N33: =TEXT('All Trades'!B33,"yyyy-mm-dd") -> yyyy-10-29 | O33: =LOG10('All Trades'!X33/Assumptions!$B$11) -> -0.30298673 | P33: =LOG10('All Trades'!AA33/Assumptions!$B$11) -> -0.00024214235
N34: =TEXT('All Trades'!B34,"yyyy-mm-dd") -> yyyy-11-05 | O34: =LOG10('All Trades'!X34/Assumptions!$B$11) -> -0.2567562 | P34: =LOG10('All Trades'!AA34/Assumptions!$B$11) -> 0.045988385
N35: =TEXT('All Trades'!B35,"yyyy-mm-dd") -> yyyy-11-12 | O35: =LOG10('All Trades'!X35/Assumptions!$B$11) -> -0.44313786 | P35: =LOG10('All Trades'!AA35/Assumptions!$B$11) -> -0.14039327
N36: =TEXT('All Trades'!B36,"yyyy-mm-dd") -> yyyy-11-19 | O36: =LOG10('All Trades'!X36/Assumptions!$B$11) -> -0.81793657 | P36: =LOG10('All Trades'!AA36/Assumptions!$B$11) -> -0.14039327
N37: =TEXT('All Trades'!B37,"yyyy-mm-dd") -> yyyy-11-26 | O37: =LOG10('All Trades'!X37/Assumptions!$B$11) -> -0.76924234 | P37: =LOG10('All Trades'!AA37/Assumptions!$B$11) -> -0.14039327
N38: =TEXT('All Trades'!B38,"yyyy-mm-dd") -> yyyy-12-03 | O38: =LOG10('All Trades'!X38/Assumptions!$B$11) -> -1.0074408 | P38: =LOG10('All Trades'!AA38/Assumptions!$B$11) -> -0.14039327
N39: =TEXT('All Trades'!B39,"yyyy-mm-dd") -> yyyy-12-10 | O39: =LOG10('All Trades'!X39/Assumptions!$B$11) -> -0.94595133 | P39: =LOG10('All Trades'!AA39/Assumptions!$B$11) -> -0.078903847
... N436: =TEXT('All Trades'!B436,"yyyy-mm-dd") -> yyyy-08-03 | O436: =LOG10('All Trades'!X436/Assumptions!$B$11) -> 6.1340573 | P436: =LOG10('All Trades'!AA436/Assumptions!$B$11) -> 7.864986

Sheet Assumptions
A1: Rule assumptions | B1: Rule assumptions | C1: Rule assumptions | D1: Rule assumptions
A2: Rule assumptions | B2: Rule assumptions | C2: Rule assumptions | D2: Rule assumptions
A3: Blue-text cells are editable. All stateful decisions on All Trades reference these cells. | B3: Blue-text cells are editable. All stateful decisions on All Trades reference these cells. | C3: Blue-text cells are editable. All stateful decisions on All Trades reference these cells. | D3: Blue-text cells are editable. All stateful decisions on All Trades reference these cells.
A5: Parameter | B5: Value | C5: Interpretation
A6: Leverage | B6: 11.3 | C6: Applied to every raw weekly return
A7: Last-two threshold | B7: -0.02 | C7: Skip when the prior two rule outcomes sum to this value or less
A8: Cash-opening gap | B8: 0.01 | C8: Friday adjusted cash close to Monday adjusted cash open
A9: 20-session momentum | B9: -0.005 | C9: Previous Friday daily close versus 20 sessions earlier
A10: Tuesday normalization | B10: 0.005 | C10: Absolute Tuesday daily open deviation from previous Friday daily close
A11: Initial comparison equity | B11: 100 | C11: Common index base for both equity paths
A13: Model conventions | B13: Model conventions | C13: Model conventions | D13: Model conventions
A14: State | B14: Skipped weeks contribute 0.0 to the next two-outcome sum
A15: Priority | B15: Damage skip is evaluated before the gap/momentum branch.
A16: Normalization anchor | B16: Previous Friday daily cash close
A17: Tuesday limitation | B17: Repriced overlay reuses the original baseline exit price; it does not rerun exit state.
A18: Source | B18: D:\oppw\backtest\oppw24.py; D:\oppw\backtest\quotes.pkl

Sheet All Trades
A1: All baseline trades versus stateful loss-control rule | B1: All baseline trades versus stateful loss-control rule | C1: All baseline trades versus stateful loss-control rule | D1: All baseline trades versus stateful loss-control rule | E1: All baseline trades versus stateful loss-control rule | F1: All baseline trades versus stateful loss-control rule | G1: All baseline trades versus stateful loss-control rule | H1: All baseline trades versus stateful loss-control rule | I1: All baseline trades versus stateful loss-control rule | J1: All baseline trades versus stateful loss-control rule | K1: All baseline trades versus stateful loss-control rule | L1: All baseline trades versus stateful loss-control rule | M1: All baseline trades versus stateful loss-control rule | N1: All baseline trades versus stateful loss-control rule | O1: All baseline trades versus stateful loss-control rule | P1: All baseline trades versus stateful loss-control rule | Q1: All baseline trades versus stateful loss-control rule | R1: All baseline trades versus stateful loss-control rule | S1: All baseline trades versus stateful loss-control rule | T1: All baseline trades versus stateful loss-control rule | U1: All baseline trades versus stateful loss-control rule | V1: All baseline trades versus stateful loss-control rule | W1: All baseline trades versus stateful loss-control rule | X1: All baseline trades versus stateful loss-control rule | Y1: All baseline trades versus stateful loss-control rule | Z1: All baseline trades versus stateful loss-control rule | AA1: All baseline trades versus stateful loss-control rule | AB1: All baseline trades versus stateful loss-control rule | AC1: All baseline trades versus stateful loss-control rule | AD1: All baseline trades versus stateful loss-control rule | AE1: All baseline trades versus stateful loss-control rule
A2: All baseline trades versus stateful loss-control rule | B2: All baseline trades versus stateful loss-control rule | C2: All baseline trades versus stateful loss-control rule | D2: All baseline trades versus stateful loss-control rule | E2: All baseline trades versus stateful loss-control rule | F2: All baseline trades versus stateful loss-control rule | G2: All baseline trades versus stateful loss-control rule | H2: All baseline trades versus stateful loss-control rule | I2: All baseline trades versus stateful loss-control rule | J2: All baseline trades versus stateful loss-control rule | K2: All baseline trades versus stateful loss-control rule | L2: All baseline trades versus stateful loss-control rule | M2: All baseline trades versus stateful loss-control rule | N2: All baseline trades versus stateful loss-control rule | O2: All baseline trades versus stateful loss-control rule | P2: All baseline trades versus stateful loss-control rule | Q2: All baseline trades versus stateful loss-control rule | R2: All baseline trades versus stateful loss-control rule | S2: All baseline trades versus stateful loss-control rule | T2: All baseline trades versus stateful loss-control rule | U2: All baseline trades versus stateful loss-control rule | V2: All baseline trades versus stateful loss-control rule | W2: All baseline trades versus stateful loss-control rule | X2: All baseline trades versus stateful loss-control rule | Y2: All baseline trades versus stateful loss-control rule | Z2: All baseline trades versus stateful loss-control rule | AA2: All baseline trades versus stateful loss-control rule | AB2: All baseline trades versus stateful loss-control rule | AC2: All baseline trades versus stateful loss-control rule | AD2: All baseline trades versus stateful loss-control rule | AE2: All baseline trades versus stateful loss-control rule
A3: One row per baseline trade. Green formula cells reference assumptions or prior rows; imported historical observations remain black. | B3: One row per baseline trade. Green formula cells reference assumptions or prior rows; imported historical observations remain black. | C3: One row per baseline trade. Green formula cells reference assumptions or prior rows; imported historical observations remain black. | D3: One row per baseline trade. Green formula cells reference assumptions or prior rows; imported historical observations remain black. | E3: One row per baseline trade. Green formula cells reference assumptions or prior rows; imported historical observations remain black. | F3: One row per baseline trade. Green formula cells reference assumptions or prior rows; imported historical observations remain black. | G3: One row per baseline trade. Green formula cells reference assumptions or prior rows; imported historical observations remain black. | H3: One row per baseline trade. Green formula cells reference assumptions or prior rows; imported historical observations remain black. | I3: One row per baseline trade. Green formula cells reference assumptions or prior rows; imported historical observations remain black. | J3: One row per baseline trade. Green formula cells reference assumptions or prior rows; imported historical observations remain black. | K3: One row per baseline trade. Green formula cells reference assumptions or prior rows; imported historical observations remain black. | L3: One row per baseline trade. Green formula cells reference assumptions or prior rows; imported historical observations remain black. | M3: One row per baseline trade. Green formula cells reference assumptions or prior rows; imported historical observations remain black. | N3: One row per baseline trade. Green formula cells reference assumptions or prior rows; imported historical observations remain black. | O3: One row per baseline trade. Green formula cells reference assumptions or prior rows; imported historical observations remain black. | P3: One row per baseline trade. Green formula cells reference assumptions or prior rows; imported historical observations remain black. | Q3: One row per baseline trade. Green formula cells reference assumptions or prior rows; imported historical observations remain black. | R3: One row per baseline trade. Green formula cells reference assumptions or prior rows; imported historical observations remain black. | S3: One row per baseline trade. Green formula cells reference assumptions or prior rows; imported historical observations remain black. | T3: One row per baseline trade. Green formula cells reference assumptions or prior rows; imported historical observations remain black. | U3: One row per baseline trade. Green formula cells reference assumptions or prior rows; imported historical observations remain black. | V3: One row per baseline trade. Green formula cells reference assumptions or prior rows; imported historical observations remain black. | W3: One row per baseline trade. Green formula cells reference assumptions or prior rows; imported historical observations remain black. | X3: One row per baseline trade. Green formula cells reference assumptions or prior rows; imported historical observations remain black. | Y3: One row per baseline trade. Green formula cells reference assumptions or prior rows; imported historical observations remain black. | Z3: One row per baseline trade. Green formula cells reference assumptions or prior rows; imported historical observations remain black. | AA3: One row per baseline trade. Green formula cells reference assumptions or prior rows; imported historical observations remain black. | AB3: One row per baseline trade. Green formula cells reference assumptions or prior rows; imported historical observations remain black. | AC3: One row per baseline trade. Green formula cells reference assumptions or prior rows; imported historical observations remain black. | AD3: One row per baseline trade. Green formula cells reference assumptions or prior rows; imported historical observations remain black. | AE3: One row per baseline trade. Green formula cells reference assumptions or prior rows; imported historical observations remain black.
A4: Trade # | B4: Open date | C4: Close date | D4: Exit reason | E4: Baseline open | F4: Baseline close | G4: Baseline raw | H4: Previous 2 rule sum | I4: Damage trigger | J4: Cash-open gap | K4: Momentum 20d | L4: Tuesday vs Friday | M4: Gap trigger | N4: Momentum trigger | O4: Tuesday normalized | P4: Tuesday date | Q4: Tuesday entry | R4: Tuesday repriced raw | S4: Rule action | T4: Rule raw | U4: Baseline 11.3x | V4: Rule 11.3x | W4: 11.3x difference | X4: Baseline equity | Y4: Baseline peak | Z4: Baseline DD | AA4: Rule equity | AB4: Rule peak | AC4: Rule DD | AD4: Equity difference | AE4: Notes
A5: 1 | B5: 43206 | C5: 43207 | D5: CH | E5: 6671.459 | F5: 6816.369 | G5: 0.02172 | H5: =0 -> 0 | I5: =AND(A5>2,H5<=Assumptions!$B$7) -> FALSE | J5: 0.0067437077 | L5: 0.017657044 | M5: =J5>=Assumptions!$B$8 -> FALSE | N5: =AND(K5<>"",K5<=Assumptions!$B$9) -> FALSE | O5: =AND(P5<>"",ABS(L5)<=Assumptions!$B$10) -> FALSE | P5: 43207 | Q5: 6741.259 | R5: 0.01114 | S5: =IF(I5,"DAMAGE SKIP",IF(AND(M5,N5),IF(O5,"TUESDAY RE-ENTRY","GAP/MOM SKIP"),"BASELINE")) -> BASELINE | T5: =IF(I5,0,IF(AND(M5,N5),IF(O5,R5,0),G5)) -> 0.02172 | U5: =G5*Assumptions!$B$6 -> 0.245436 | V5: =T5*Assumptions!$B$6 -> 0.245436 | W5: =V5-U5 -> 0 | X5: =Assumptions!$B$11*(1+U5) -> 124.5436 | Y5: =MAX(Assumptions!$B$11,X5) -> 124.5436 | Z5: =X5/Y5-1 -> 0 | AA5: =Assumptions!$B$11*(1+V5) -> 124.5436 | AB5: =MAX(Assumptions!$B$11,AA5) -> 124.5436 | AC5: =AA5/AB5-1 -> 0 | AD5: =AA5-X5 -> 0 | AE5: Baseline trade unchanged.
A6: 2 | B6: 43213 | C6: 43216 | D6: TSL1PRE | E6: 6695.27 | F6: 6581.359 | G6: -0.01701 | H6: =0 -> 0 | I6: =AND(A6>2,H6<=Assumptions!$B$7) -> FALSE | J6: 0.0039754023 | L6: 0.0020431519 | M6: =J6>=Assumptions!$B$8 -> FALSE | N6: =AND(K6<>"",K6<=Assumptions!$B$9) -> FALSE | O6: =AND(P6<>"",ABS(L6)<=Assumptions!$B$10) -> TRUE | P6: 43214 | Q6: 6678.369 | R6: -0.01452 | S6: =IF(I6,"DAMAGE SKIP",IF(AND(M6,N6),IF(O6,"TUESDAY RE-ENTRY","GAP/MOM SKIP"),"BASELINE")) -> BASELINE | T6: =IF(I6,0,IF(AND(M6,N6),IF(O6,R6,0),G6)) -> -0.01701 | U6: =G6*Assumptions!$B$6 -> -0.192213 | V6: =T6*Assumptions!$B$6 -> -0.192213 | W6: =V6-U6 -> 0 | X6: =X5*(1+U6) -> 100.6047 | Y6: =MAX(Y5,X6) -> 124.5436 | Z6: =X6/Y6-1 -> -0.192213 | AA6: =AA5*(1+V6) -> 100.6047 | AB6: =MAX(AB5,AA6) -> 124.5436 | AC6: =AA6/AB6-1 -> -0.192213 | AD6: =AA6-X6 -> 0 | AE6: Baseline trade unchanged.
A7: 3 | B7: 43220 | C7: 43223 | D7: TSL1PRE | E7: 6669.27 | F7: 6628.76 | G7: -0.00607 | H7: =SUM(T5:T6) -> 0.00471 | I7: =AND(A7>2,H7<=Assumptions!$B$7) -> FALSE | J7: 0.0014416632 | L7: -0.0096524847 | M7: =J7>=Assumptions!$B$8 -> FALSE | N7: =AND(K7<>"",K7<=Assumptions!$B$9) -> FALSE | O7: =AND(P7<>"",ABS(L7)<=Assumptions!$B$10) -> FALSE | P7: 43221 | Q7: 6590.459 | R7: 0.00581 | S7: =IF(I7,"DAMAGE SKIP",IF(AND(M7,N7),IF(O7,"TUESDAY RE-ENTRY","GAP/MOM SKIP"),"BASELINE")) -> BASELINE | T7: =IF(I7,0,IF(AND(M7,N7),IF(O7,R7,0),G7)) -> -0.00607 | U7: =G7*Assumptions!$B$6 -> -0.068591 | V7: =T7*Assumptions!$B$6 -> -0.068591 | W7: =V7-U7 -> 0 | X7: =X6*(1+U7) -> 93.704124 | Y7: =MAX(Y6,X7) -> 124.5436 | Z7: =X7/Y7-1 -> -0.24761992 | AA7: =AA6*(1+V7) -> 93.704124 | AB7: =MAX(AB6,AA7) -> 124.5436 | AC7: =AA7/AB7-1 -> -0.24761992 | AD7: =AA7-X7 -> 0 | AE7: Baseline trade unchanged.
A8: 4 | B8: 43227 | C8: 43231 | D8: TO | E8: 6796.769 | F8: 6952.159 | G8: 0.02286 | H8: =SUM(T6:T7) -> -0.02308 | I8: =AND(A8>2,H8<=Assumptions!$B$7) -> TRUE | J8: 0.0044332821 | L8: 0.0056134009 | M8: =J8>=Assumptions!$B$8 -> FALSE | N8: =AND(K8<>"",K8<=Assumptions!$B$9) -> FALSE | O8: =AND(P8<>"",ABS(L8)<=Assumptions!$B$10) -> FALSE | P8: 43228 | Q8: 6807.36 | R8: 0.02127 | S8: =IF(I8,"DAMAGE SKIP",IF(AND(M8,N8),IF(O8,"TUESDAY RE-ENTRY","GAP/MOM SKIP"),"BASELINE")) -> DAMAGE SKIP | T8: =IF(I8,0,IF(AND(M8,N8),IF(O8,R8,0),G8)) -> 0 | U8: =G8*Assumptions!$B$6 -> 0.258318 | V8: =T8*Assumptions!$B$6 -> 0 | W8: =V8-U8 -> -0.258318 | X8: =X7*(1+U8) -> 117.90959 | Y8: =MAX(Y7,X8) -> 124.5436 | Z8: =X8/Y8-1 -> -0.0532666 | AA8: =AA7*(1+V8) -> 93.704124 | AB8: =MAX(AB7,AA8) -> 124.5436 | AC8: =AA8/AB8-1 -> -0.24761992 | AD8: =AA8-X8 -> -24.205462 | AE8: Skipped because the previous two rule outcomes totalled at or below the damage threshold.
A9: 5 | B9: 43234 | C9: 43236 | D9: BH | E9: 6967.459 | F9: 6939.5892 | G9: -0.004 | H9: =SUM(T7:T8) -> -0.00607 | I9: =AND(A9>2,H9<=Assumptions!$B$7) -> FALSE | J9: 0.0022007552 | K9: 0.050415249 | L9: -0.0063709253 | M9: =J9>=Assumptions!$B$8 -> FALSE | N9: =AND(K9<>"",K9<=Assumptions!$B$9) -> FALSE | O9: =AND(P9<>"",ABS(L9)<=Assumptions!$B$10) -> FALSE | P9: 43235 | Q9: 6907.26 | R9: 0.00468 | S9: =IF(I9,"DAMAGE SKIP",IF(AND(M9,N9),IF(O9,"TUESDAY RE-ENTRY","GAP/MOM SKIP"),"BASELINE")) -> BASELINE | T9: =IF(I9,0,IF(AND(M9,N9),IF(O9,R9,0),G9)) -> -0.004 | U9: =G9*Assumptions!$B$6 -> -0.0452 | V9: =T9*Assumptions!$B$6 -> -0.0452 | W9: =V9-U9 -> 0 | X9: =X8*(1+U9) -> 112.58007 | Y9: =MAX(Y8,X9) -> 124.5436 | Z9: =X9/Y9-1 -> -0.09605895 | AA9: =AA8*(1+V9) -> 89.468698 | AB9: =MAX(AB8,AA9) -> 124.5436 | AC9: =AA9/AB9-1 -> -0.2816275 | AD9: =AA9-X9 -> -23.111375 | AE9: Baseline trade unchanged.
A10: 6 | B10: 43241 | C10: 43244 | D10: TSL2 | E10: 6917.269 | F10: 6889.5999 | G10: -0.004 | H10: =SUM(T8:T9) -> -0.004 | I10: =AND(A10>2,H10<=Assumptions!$B$7) -> FALSE | J10: 0.0073410565 | K10: 0.03182403 | L10: 0.010195194 | M10: =J10>=Assumptions!$B$8 -> FALSE | N10: =AND(K10<>"",K10<=Assumptions!$B$9) -> FALSE | O10: =AND(P10<>"",ABS(L10)<=Assumptions!$B$10) -> FALSE | P10: 43242 | Q10: 6934.57 | R10: -0.00648 | S10: =IF(I10,"DAMAGE SKIP",IF(AND(M10,N10),IF(O10,"TUESDAY RE-ENTRY","GAP/MOM SKIP"),"BASELINE")) -> BASELINE | T10: =IF(I10,0,IF(AND(M10,N10),IF(O10,R10,0),G10)) -> -0.004 | U10: =G10*Assumptions!$B$6 -> -0.0452 | V10: =T10*Assumptions!$B$6 -> -0.0452 | W10: =V10-U10 -> 0 | X10: =X9*(1+U10) -> 107.49145 | Y10: =MAX(Y9,X10) -> 124.5436 | Z10: =X10/Y10-1 -> -0.13691709 | AA10: =AA9*(1+V10) -> 85.424712 | AB10: =MAX(AB9,AA10) -> 124.5436 | AC10: =AA10/AB10-1 -> -0.31409793 | AD10: =AA10-X10 -> -22.066741 | AE10: Baseline trade unchanged.
A11: 7 | B11: 43249 | C11: 43252 | D11: TO | E11: 6923.56 | F11: 7080.37 | G11: 0.02264 | H11: =SUM(T9:T10) -> -0.008 | I11: =AND(A11>2,H11<=Assumptions!$B$7) -> FALSE | J11: -0.0041867375 | K11: 0.047278401 | M11: =J11>=Assumptions!$B$8 -> FALSE | N11: =AND(K11<>"",K11<=Assumptions!$B$9) -> FALSE | O11: =AND(P11<>"",ABS(L11)<=Assumptions!$B$10) -> FALSE | S11: =IF(I11,"DAMAGE SKIP",IF(AND(M11,N11),IF(O11,"TUESDAY RE-ENTRY","GAP/MOM SKIP"),"BASELINE")) -> BASELINE | T11: =IF(I11,0,IF(AND(M11,N11),IF(O11,R11,0),G11)) -> 0.02264 | U11: =G11*Assumptions!$B$6 -> 0.255832 | V11: =T11*Assumptions!$B$6 -> 0.255832 | W11: =V11-U11 -> 0 | X11: =X10*(1+U11) -> 134.99121 | Y11: =MAX(Y10,X11) -> 134.99121 | Z11: =X11/Y11-1 -> 0 | AA11: =AA10*(1+V11) -> 107.27909 | AB11: =MAX(AB10,AA11) -> 124.5436 | AC11: =AA11/AB11-1 -> -0.13862224 | AD11: =AA11-X11 -> -27.712119 | AE11: Baseline trade unchanged.
A12: 8 | B12: 43255 | C12: 43259 | D12: TO | E12: 7098.059 | F12: 7151.26 | G12: 0.00749 | H12: =SUM(T10:T11) -> 0.01864 | I12: =AND(A12>2,H12<=Assumptions!$B$7) -> FALSE | J12: 0.0024983158 | K12: 0.067717792 | L12: 0.011176917 | M12: =J12>=Assumptions!$B$8 -> FALSE | N12: =AND(K12<>"",K12<=Assumptions!$B$9) -> FALSE | O12: =AND(P12<>"",ABS(L12)<=Assumptions!$B$10) -> FALSE | P12: 43256 | Q12: 7159.97 | R12: -0.00121 | S12: =IF(I12,"DAMAGE SKIP",IF(AND(M12,N12),IF(O12,"TUESDAY RE-ENTRY","GAP/MOM SKIP"),"BASELINE")) -> BASELINE | T12: =IF(I12,0,IF(AND(M12,N12),IF(O12,R12,0),G12)) -> 0.00749 | U12: =G12*Assumptions!$B$6 -> 0.084637 | V12: =T12*Assumptions!$B$6 -> 0.084637 | W12: =V12-U12 -> 0 | X12: =X11*(1+U12) -> 146.41646 | Y12: =MAX(Y11,X12) -> 146.41646 | Z12: =X12/Y12-1 -> 0 | AA12: =AA11*(1+V12) -> 116.35887 | AB12: =MAX(AB11,AA12) -> 124.5436 | AC12: =AA12/AB12-1 -> -0.065717808 | AD12: =AA12-X12 -> -30.05759 | AE12: Baseline trade unchanged.
A13: 9 | B13: 43262 | C13: 43266 | D13: TO | E13: 7143.46 | F13: 7254.959 | G13: 0.0156 | H13: =SUM(T11:T12) -> 0.03013 | I13: =AND(A13>2,H13<=Assumptions!$B$7) -> FALSE | J13: -0.0010907169 | K13: 0.028254388 | L13: 0.0039520699 | M13: =J13>=Assumptions!$B$8 -> FALSE | N13: =AND(K13<>"",K13<=Assumptions!$B$9) -> FALSE | O13: =AND(P13<>"",ABS(L13)<=Assumptions!$B$10) -> TRUE | P13: 43263 | Q13: 7180.46 | R13: 0.01037 | S13: =IF(I13,"DAMAGE SKIP",IF(AND(M13,N13),IF(O13,"TUESDAY RE-ENTRY","GAP/MOM SKIP"),"BASELINE")) -> BASELINE | T13: =IF(I13,0,IF(AND(M13,N13),IF(O13,R13,0),G13)) -> 0.0156 | U13: =G13*Assumptions!$B$6 -> 0.17628 | V13: =T13*Assumptions!$B$6 -> 0.17628 | W13: =V13-U13 -> 0 | X13: =X12*(1+U13) -> 172.22675 | Y13: =MAX(Y12,X13) -> 172.22675 | Z13: =X13/Y13-1 -> 0 | AA13: =AA12*(1+V13) -> 136.87061 | AB13: =MAX(AB12,AA13) -> 136.87061 | AC13: =AA13/AB13-1 -> 0 | AD13: =AA13-X13 -> -35.356142 | AE13: Baseline trade unchanged.
A14: 10 | B14: 43269 | C14: 43273 | D14: TSL4 | E14: 7206.469 | F14: 7177.6431 | G14: -0.004 | H14: =SUM(T12:T13) -> 0.02309 | I14: =AND(A14>2,H14<=Assumptions!$B$7) -> FALSE | J14: -0.0066837042 | K14: 0.05140353 | L14: -0.013328353 | M14: =J14>=Assumptions!$B$8 -> FALSE | N14: =AND(K14<>"",K14<=Assumptions!$B$9) -> FALSE | O14: =AND(P14<>"",ABS(L14)<=Assumptions!$B$10) -> FALSE | P14: 43270 | Q14: 7155.46 | R14: 0.0031 | S14: =IF(I14,"DAMAGE SKIP",IF(AND(M14,N14),IF(O14,"TUESDAY RE-ENTRY","GAP/MOM SKIP"),"BASELINE")) -> BASELINE | T14: =IF(I14,0,IF(AND(M14,N14),IF(O14,R14,0),G14)) -> -0.004 | U14: =G14*Assumptions!$B$6 -> -0.0452 | V14: =T14*Assumptions!$B$6 -> -0.0452 | W14: =V14-U14 -> 0 | X14: =X13*(1+U14) -> 164.4421 | Y14: =MAX(Y13,X14) -> 172.22675 | Z14: =X14/Y14-1 -> -0.0452 | AA14: =AA13*(1+V14) -> 130.68406 | AB14: =MAX(AB13,AA14) -> 136.87061 | AC14: =AA14/AB14-1 -> -0.0452 | AD14: =AA14-X14 -> -33.758044 | AE14: Baseline trade unchanged.
A15: 11 | B15: 43276 | C15: 43278 | D15: BH | E15: 7134.27 | F15: 7105.7329 | G15: -0.004 | H15: =SUM(T13:T14) -> 0.0116 | I15: =AND(A15>2,H15<=Assumptions!$B$7) -> FALSE | J15: -0.0097150852 | K15: 0.036094404 | L15: -0.018974301 | M15: =J15>=Assumptions!$B$8 -> FALSE | N15: =AND(K15<>"",K15<=Assumptions!$B$9) -> FALSE | O15: =AND(P15<>"",ABS(L15)<=Assumptions!$B$10) -> FALSE | P15: 43277 | Q15: 7064.769 | R15: 0.00579 | S15: =IF(I15,"DAMAGE SKIP",IF(AND(M15,N15),IF(O15,"TUESDAY RE-ENTRY","GAP/MOM SKIP"),"BASELINE")) -> BASELINE | T15: =IF(I15,0,IF(AND(M15,N15),IF(O15,R15,0),G15)) -> -0.004 | U15: =G15*Assumptions!$B$6 -> -0.0452 | V15: =T15*Assumptions!$B$6 -> -0.0452 | W15: =V15-U15 -> 0 | X15: =X14*(1+U15) -> 157.00932 | Y15: =MAX(Y14,X15) -> 172.22675 | Z15: =X15/Y15-1 -> -0.08835696 | AA15: =AA14*(1+V15) -> 124.77714 | AB15: =MAX(AB14,AA15) -> 136.87061 | AC15: =AA15/AB15-1 -> -0.08835696 | AD15: =AA15-X15 -> -32.232181 | AE15: Baseline trade unchanged.
A16: 12 | B16: 43283 | C16: 43283 | D16: CH | E16: 6981.27 | F16: 7096.859 | G16: 0.01655 | H16: =SUM(T14:T15) -> -0.008 | I16: =AND(A16>2,H16<=Assumptions!$B$7) -> FALSE | J16: -0.010208031 | K16: -0.0041731207 | L16: 0.010168478 | M16: =J16>=Assumptions!$B$8 -> FALSE | N16: =AND(K16<>"",K16<=Assumptions!$B$9) -> FALSE | O16: =AND(P16<>"",ABS(L16)<=Assumptions!$B$10) -> FALSE | P16: 43284 | Q16: 7121.87 | R16: -0.00351 | S16: =IF(I16,"DAMAGE SKIP",IF(AND(M16,N16),IF(O16,"TUESDAY RE-ENTRY","GAP/MOM SKIP"),"BASELINE")) -> BASELINE | T16: =IF(I16,0,IF(AND(M16,N16),IF(O16,R16,0),G16)) -> 0.01655 | U16: =G16*Assumptions!$B$6 -> 0.187015 | V16: =T16*Assumptions!$B$6 -> 0.187015 | W16: =V16-U16 -> 0 | X16: =X15*(1+U16) -> 186.37242 | Y16: =MAX(Y15,X16) -> 186.37242 | Z16: =X16/Y16-1 -> 0 | AA16: =AA15*(1+V16) -> 148.11233 | AB16: =MAX(AB15,AA16) -> 148.11233 | AC16: =AA16/AB16-1 -> 0 | AD16: =AA16-X16 -> -38.260082 | AE16: Baseline trade unchanged.
A17: 13 | B17: 43290 | C17: 43294 | D17: TO | E17: 7246.769 | F17: 7373.869 | G17: 0.01753 | H17: =SUM(T15:T16) -> 0.01255 | I17: =AND(A17>2,H17<=Assumptions!$B$7) -> FALSE | J17: 0.0052030313 | K17: 0.0088972039 | L17: 0.010339214 | M17: =J17>=Assumptions!$B$8 -> FALSE | N17: =AND(K17<>"",K17<=Assumptions!$B$9) -> FALSE | O17: =AND(P17<>"",ABS(L17)<=Assumptions!$B$10) -> FALSE | P17: 43291 | Q17: 7285.66 | R17: 0.0121 | S17: =IF(I17,"DAMAGE SKIP",IF(AND(M17,N17),IF(O17,"TUESDAY RE-ENTRY","GAP/MOM SKIP"),"BASELINE")) -> BASELINE | T17: =IF(I17,0,IF(AND(M17,N17),IF(O17,R17,0),G17)) -> 0.01753 | U17: =G17*Assumptions!$B$6 -> 0.198089 | V17: =T17*Assumptions!$B$6 -> 0.198089 | W17: =V17-U17 -> 0 | X17: =X16*(1+U17) -> 223.29074 | Y17: =MAX(Y16,X17) -> 223.29074 | Z17: =X17/Y17-1 -> 0 | AA17: =AA16*(1+V17) -> 177.45176 | AB17: =MAX(AB16,AA17) -> 177.45176 | AC17: =AA17/AB17-1 -> 0 | AD17: =AA17-X17 -> -45.838983 | AE17: Baseline trade unchanged.
A18: 14 | B18: 43297 | C18: 43300 | D18: TSL2 | E18: 7375.97 | F18: 7346.4661 | G18: -0.004 | H18: =SUM(T16:T17) -> 0.03408 | I18: =AND(A18>2,H18<=Assumptions!$B$7) -> FALSE | J18: 0.00028492505 | K18: 0.013369095 | L18: -0.01273217 | M18: =J18>=Assumptions!$B$8 -> FALSE | N18: =AND(K18<>"",K18<=Assumptions!$B$9) -> FALSE | O18: =AND(P18<>"",ABS(L18)<=Assumptions!$B$10) -> FALSE | P18: 43298 | Q18: 7277.659 | R18: 0.00945 | S18: =IF(I18,"DAMAGE SKIP",IF(AND(M18,N18),IF(O18,"TUESDAY RE-ENTRY","GAP/MOM SKIP"),"BASELINE")) -> BASELINE | T18: =IF(I18,0,IF(AND(M18,N18),IF(O18,R18,0),G18)) -> -0.004 | U18: =G18*Assumptions!$B$6 -> -0.0452 | V18: =T18*Assumptions!$B$6 -> -0.0452 | W18: =V18-U18 -> 0 | X18: =X17*(1+U18) -> 213.198 | Y18: =MAX(Y17,X18) -> 223.29074 | Z18: =X18/Y18-1 -> -0.0452 | AA18: =AA17*(1+V18) -> 169.43094 | AB18: =MAX(AB17,AA18) -> 177.45176 | AC18: =AA18/AB18-1 -> -0.0452 | AD18: =AA18-X18 -> -43.767061 | AE18: Baseline trade unchanged.
A19: 15 | B19: 43304 | C19: 43305 | D19: PREOH | E19: 7325.86 | F19: 7405.869 | G19: 0.01092 | H19: =SUM(T17:T18) -> 0.01353 | I19: =AND(A19>2,H19<=Assumptions!$B$7) -> FALSE | J19: -0.0031446584 | K19: 0.018681843 | L19: 0.013366872 | M19: =J19>=Assumptions!$B$8 -> FALSE | N19: =AND(K19<>"",K19<=Assumptions!$B$9) -> FALSE | O19: =AND(P19<>"",ABS(L19)<=Assumptions!$B$10) -> FALSE | P19: 43305 | Q19: 7449.67 | R19: -0.00587 | S19: =IF(I19,"DAMAGE SKIP",IF(AND(M19,N19),IF(O19,"TUESDAY RE-ENTRY","GAP/MOM SKIP"),"BASELINE")) -> BASELINE | T19: =IF(I19,0,IF(AND(M19,N19),IF(O19,R19,0),G19)) -> 0.01092 | U19: =G19*Assumptions!$B$6 -> 0.123396 | V19: =T19*Assumptions!$B$6 -> 0.123396 | W19: =V19-U19 -> 0 | X19: =X18*(1+U19) -> 239.50578 | Y19: =MAX(Y18,X19) -> 239.50578 | Z19: =X19/Y19-1 -> 0 | AA19: =AA18*(1+V19) -> 190.33804 | AB19: =MAX(AB18,AA19) -> 190.33804 | AC19: =AA19/AB19-1 -> 0 | AD19: =AA19-X19 -> -49.167742 | AE19: Baseline trade unchanged.
A20: 16 | B20: 43311 | C20: 43313 | D20: BEPRE | E20: 7294.669 | F20: 7282.07 | G20: -0.00172 | H20: =SUM(T18:T19) -> 0.00692 | I20: =AND(A20>2,H20<=Assumptions!$B$7) -> FALSE | J20: 6.9781853e-05 | K20: 0.037660717 | L20: -0.010575149 | M20: =J20>=Assumptions!$B$8 -> FALSE | N20: =AND(K20<>"",K20<=Assumptions!$B$9) -> FALSE | O20: =AND(P20<>"",ABS(L20)<=Assumptions!$B$10) -> FALSE | P20: 43312 | Q20: 7216.2 | R20: 0.00912 | S20: =IF(I20,"DAMAGE SKIP",IF(AND(M20,N20),IF(O20,"TUESDAY RE-ENTRY","GAP/MOM SKIP"),"BASELINE")) -> BASELINE | T20: =IF(I20,0,IF(AND(M20,N20),IF(O20,R20,0),G20)) -> -0.00172 | U20: =G20*Assumptions!$B$6 -> -0.019436 | V20: =T20*Assumptions!$B$6 -> -0.019436 | W20: =V20-U20 -> 0 | X20: =X19*(1+U20) -> 234.85075 | Y20: =MAX(Y19,X20) -> 239.50578 | Z20: =X20/Y20-1 -> -0.019436 | AA20: =AA19*(1+V20) -> 186.63863 | AB20: =MAX(AB19,AA20) -> 190.33804 | AC20: =AA20/AB20-1 -> -0.019436 | AD20: =AA20-X20 -> -48.212117 | AE20: Baseline trade unchanged.
A21: 17 | B21: 43318 | C21: 43322 | D21: TO | E21: 7388.67 | F21: 7410.67 | G21: 0.00297 | H21: =SUM(T19:T20) -> 0.0092 | I21: =AND(A21>2,H21<=Assumptions!$B$7) -> FALSE | J21: -0.00082477221 | K21: 0.025490278 | L21: 0.008611166 | M21: =J21>=Assumptions!$B$8 -> FALSE | N21: =AND(K21<>"",K21<=Assumptions!$B$9) -> FALSE | O21: =AND(P21<>"",ABS(L21)<=Assumptions!$B$10) -> FALSE | P21: 43319 | Q21: 7456.76 | R21: -0.00618 | S21: =IF(I21,"DAMAGE SKIP",IF(AND(M21,N21),IF(O21,"TUESDAY RE-ENTRY","GAP/MOM SKIP"),"BASELINE")) -> BASELINE | T21: =IF(I21,0,IF(AND(M21,N21),IF(O21,R21,0),G21)) -> 0.00297 | U21: =G21*Assumptions!$B$6 -> 0.033561 | V21: =T21*Assumptions!$B$6 -> 0.033561 | W21: =V21-U21 -> 0 | X21: =X20*(1+U21) -> 242.73257 | Y21: =MAX(Y20,X21) -> 242.73257 | Z21: =X21/Y21-1 -> 0 | AA21: =AA20*(1+V21) -> 192.90241 | AB21: =MAX(AB20,AA21) -> 192.90241 | AC21: =AA21/AB21-1 -> 0 | AD21: =AA21-X21 -> -49.830164 | AE21: Baseline trade unchanged.
A22: 18 | B22: 43325 | C22: 43328 | D22: TSL1PRE | E22: 7419.96 | F22: 7366.47 | G22: -0.0072 | H22: =SUM(T20:T21) -> 0.00125 | I22: =AND(A22>2,H22<=Assumptions!$B$7) -> FALSE | J22: 0.0012535979 | K22: 0.0050951998 | L22: 0.0026680896 | M22: =J22>=Assumptions!$B$8 -> FALSE | N22: =AND(K22<>"",K22<=Assumptions!$B$9) -> FALSE | O22: =AND(P22<>"",ABS(L22)<=Assumptions!$B$10) -> TRUE | P22: 43326 | Q22: 7426.969 | R22: -0.00814 | S22: =IF(I22,"DAMAGE SKIP",IF(AND(M22,N22),IF(O22,"TUESDAY RE-ENTRY","GAP/MOM SKIP"),"BASELINE")) -> BASELINE | T22: =IF(I22,0,IF(AND(M22,N22),IF(O22,R22,0),G22)) -> -0.0072 | U22: =G22*Assumptions!$B$6 -> -0.08136 | V22: =T22*Assumptions!$B$6 -> -0.08136 | W22: =V22-U22 -> 0 | X22: =X21*(1+U22) -> 222.98385 | Y22: =MAX(Y21,X22) -> 242.73257 | Z22: =X22/Y22-1 -> -0.08136 | AA22: =AA21*(1+V22) -> 177.20787 | AB22: =MAX(AB21,AA22) -> 192.90241 | AC22: =AA22/AB22-1 -> -0.08136 | AD22: =AA22-X22 -> -45.775982 | AE22: Baseline trade unchanged.
A23: 19 | B23: 43332 | C23: 43336 | D23: TO | E23: 7393.27 | F23: 7484.959 | G23: 0.0124 | H23: =SUM(T21:T22) -> -0.00423 | I23: =AND(A23>2,H23<=Assumptions!$B$7) -> FALSE | J23: 0.0022382458 | K23: 0.0048319635 | L23: 0.0022122477 | M23: =J23>=Assumptions!$B$8 -> FALSE | N23: =AND(K23<>"",K23<=Assumptions!$B$9) -> FALSE | O23: =AND(P23<>"",ABS(L23)<=Assumptions!$B$10) -> TRUE | P23: 43333 | Q23: 7391.769 | R23: 0.0126 | S23: =IF(I23,"DAMAGE SKIP",IF(AND(M23,N23),IF(O23,"TUESDAY RE-ENTRY","GAP/MOM SKIP"),"BASELINE")) -> BASELINE | T23: =IF(I23,0,IF(AND(M23,N23),IF(O23,R23,0),G23)) -> 0.0124 | U23: =G23*Assumptions!$B$6 -> 0.14012 | V23: =T23*Assumptions!$B$6 -> 0.14012 | W23: =V23-U23 -> 0 | X23: =X22*(1+U23) -> 254.22835 | Y23: =MAX(Y22,X23) -> 254.22835 | Z23: =X23/Y23-1 -> 0 | AA23: =AA22*(1+V23) -> 202.03823 | AB23: =MAX(AB22,AA23) -> 202.03823 | AC23: =AA23/AB23-1 -> 0 | AD23: =AA23-X23 -> -52.190113 | AE23: Baseline trade unchanged.
A24: 20 | B24: 43339 | C24: 43343 | D24: TO | E24: 7521.159 | F24: 7651.67 | G24: 0.01735 | H24: =SUM(T22:T23) -> 0.0052 | I24: =AND(A24>2,H24<=Assumptions!$B$7) -> FALSE | J24: 0.0048363658 | K24: 0.027274924 | L24: 0.012647042 | M24: =J24>=Assumptions!$B$8 -> FALSE | N24: =AND(K24<>"",K24<=Assumptions!$B$9) -> FALSE | O24: =AND(P24<>"",ABS(L24)<=Assumptions!$B$10) -> FALSE | P24: 43340 | Q24: 7578.359 | R24: 0.00967 | S24: =IF(I24,"DAMAGE SKIP",IF(AND(M24,N24),IF(O24,"TUESDAY RE-ENTRY","GAP/MOM SKIP"),"BASELINE")) -> BASELINE | T24: =IF(I24,0,IF(AND(M24,N24),IF(O24,R24,0),G24)) -> 0.01735 | U24: =G24*Assumptions!$B$6 -> 0.196055 | V24: =T24*Assumptions!$B$6 -> 0.196055 | W24: =V24-U24 -> 0 | X24: =X23*(1+U24) -> 304.07109 | Y24: =MAX(Y23,X24) -> 304.07109 | Z24: =X24/Y24-1 -> 0 | AA24: =AA23*(1+V24) -> 241.64884 | AB24: =MAX(AB23,AA24) -> 241.64884 | AC24: =AA24/AB24-1 -> 0 | AD24: =AA24-X24 -> -62.422245 | AE24: Baseline trade unchanged.
A25: 21 | B25: 43347 | C25: 43349 | D25: TSL1PRE | E25: 7629.759 | F25: 7525.76 | G25: -0.01363 | H25: =SUM(T23:T24) -> 0.02975 | I25: =AND(A25>2,H25<=Assumptions!$B$7) -> FALSE | J25: -0.0028635579 | K25: 0.036485528 | M25: =J25>=Assumptions!$B$8 -> FALSE | N25: =AND(K25<>"",K25<=Assumptions!$B$9) -> FALSE | O25: =AND(P25<>"",ABS(L25)<=Assumptions!$B$10) -> FALSE | S25: =IF(I25,"DAMAGE SKIP",IF(AND(M25,N25),IF(O25,"TUESDAY RE-ENTRY","GAP/MOM SKIP"),"BASELINE")) -> BASELINE | T25: =IF(I25,0,IF(AND(M25,N25),IF(O25,R25,0),G25)) -> -0.01363 | U25: =G25*Assumptions!$B$6 -> -0.154019 | V25: =T25*Assumptions!$B$6 -> -0.154019 | W25: =V25-U25 -> 0 | X25: =X24*(1+U25) -> 257.23836 | Y25: =MAX(Y24,X25) -> 304.07109 | Z25: =X25/Y25-1 -> -0.154019 | AA25: =AA24*(1+V25) -> 204.43033 | AB25: =MAX(AB24,AA25) -> 241.64884 | AC25: =AA25/AB25-1 -> -0.154019 | AD25: =AA25-X25 -> -52.808033 | AE25: Baseline trade unchanged.
A26: 22 | B26: 43353 | C26: 43357 | D26: TO | E26: 7465.77 | F26: 7546.66 | G26: 0.01083 | H26: =SUM(T24:T25) -> 0.00372 | I26: =AND(A26>2,H26<=Assumptions!$B$7) -> FALSE | J26: 0.0057265945 | K26: -0.0043518055 | L26: -0.00079206776 | M26: =J26>=Assumptions!$B$8 -> FALSE | N26: =AND(K26<>"",K26<=Assumptions!$B$9) -> FALSE | O26: =AND(P26<>"",ABS(L26)<=Assumptions!$B$10) -> TRUE | P26: 43354 | Q26: 7417.665 | R26: 0.01739 | S26: =IF(I26,"DAMAGE SKIP",IF(AND(M26,N26),IF(O26,"TUESDAY RE-ENTRY","GAP/MOM SKIP"),"BASELINE")) -> BASELINE | T26: =IF(I26,0,IF(AND(M26,N26),IF(O26,R26,0),G26)) -> 0.01083 | U26: =G26*Assumptions!$B$6 -> 0.122379 | V26: =T26*Assumptions!$B$6 -> 0.122379 | W26: =V26-U26 -> 0 | X26: =X25*(1+U26) -> 288.71893 | Y26: =MAX(Y25,X26) -> 304.07109 | Z26: =X26/Y26-1 -> -0.050488691 | AA26: =AA25*(1+V26) -> 229.44831 | AB26: =MAX(AB25,AA26) -> 241.64884 | AC26: =AA26/AB26-1 -> -0.050488691 | AD26: =AA26-X26 -> -59.270628 | AE26: Baseline trade unchanged.
A27: 23 | B27: 43360 | C27: 43362 | D27: BEPRE | E27: 7527.07 | F27: 7497.169 | G27: -0.00397 | H27: =SUM(T25:T26) -> -0.0028 | I27: =AND(A27>2,H27<=Assumptions!$B$7) -> FALSE | J27: -0.0025958503 | K27: 0.023216542 | L27: -0.013424919 | M27: =J27>=Assumptions!$B$8 -> FALSE | N27: =AND(K27<>"",K27<=Assumptions!$B$9) -> FALSE | O27: =AND(P27<>"",ABS(L27)<=Assumptions!$B$10) -> FALSE | P27: 43361 | Q27: 7438.859 | R27: 0.00783 | S27: =IF(I27,"DAMAGE SKIP",IF(AND(M27,N27),IF(O27,"TUESDAY RE-ENTRY","GAP/MOM SKIP"),"BASELINE")) -> BASELINE | T27: =IF(I27,0,IF(AND(M27,N27),IF(O27,R27,0),G27)) -> -0.00397 | U27: =G27*Assumptions!$B$6 -> -0.044861 | V27: =T27*Assumptions!$B$6 -> -0.044861 | W27: =V27-U27 -> 0 | X27: =X26*(1+U27) -> 275.76671 | Y27: =MAX(Y26,X27) -> 304.07109 | Z27: =X27/Y27-1 -> -0.093084718 | AA27: =AA26*(1+V27) -> 219.15503 | AB27: =MAX(AB26,AA27) -> 241.64884 | AC27: =AA27/AB27-1 -> -0.093084718 | AD27: =AA27-X27 -> -56.611688 | AE27: Baseline trade unchanged.
A28: 24 | B28: 43367 | C28: 43367 | D28: CH | E28: 7473.769 | F28: 7555.069 | G28: 0.01087 | H28: =SUM(T26:T27) -> 0.00686 | I28: =AND(A28>2,H28<=Assumptions!$B$7) -> FALSE | J28: -0.0073053111 | K28: 0.016070002 | L28: 0.0021087788 | M28: =J28>=Assumptions!$B$8 -> FALSE | N28: =AND(K28<>"",K28<=Assumptions!$B$9) -> FALSE | O28: =AND(P28<>"",ABS(L28)<=Assumptions!$B$10) -> TRUE | P28: 43368 | Q28: 7544.06 | R28: 0.00145 | S28: =IF(I28,"DAMAGE SKIP",IF(AND(M28,N28),IF(O28,"TUESDAY RE-ENTRY","GAP/MOM SKIP"),"BASELINE")) -> BASELINE | T28: =IF(I28,0,IF(AND(M28,N28),IF(O28,R28,0),G28)) -> 0.01087 | U28: =G28*Assumptions!$B$6 -> 0.122831 | V28: =T28*Assumptions!$B$6 -> 0.122831 | W28: =V28-U28 -> 0 | X28: =X27*(1+U28) -> 309.63942 | Y28: =MAX(Y27,X28) -> 309.63942 | Z28: =X28/Y28-1 -> 0 | AA28: =AA27*(1+V28) -> 246.07406 | AB28: =MAX(AB27,AA28) -> 246.07406 | AC28: =AA28/AB28-1 -> 0 | AD28: =AA28-X28 -> -63.565358 | AE28: Baseline trade unchanged.
A29: 25 | B29: 43374 | C29: 43376 | D29: BEPRE | E29: 7671.07 | F29: 7641.87 | G29: -0.0038 | H29: =SUM(T27:T28) -> 0.0069 | I29: =AND(A29>2,H29<=Assumptions!$B$7) -> FALSE | J29: 0.0047677241 | K29: -0.0015614819 | L29: 0.00088884888 | M29: =J29>=Assumptions!$B$8 -> FALSE | N29: =AND(K29<>"",K29<=Assumptions!$B$9) -> FALSE | O29: =AND(P29<>"",ABS(L29)<=Assumptions!$B$10) -> TRUE | P29: 43375 | Q29: 7634.959 | R29: 0.0009 | S29: =IF(I29,"DAMAGE SKIP",IF(AND(M29,N29),IF(O29,"TUESDAY RE-ENTRY","GAP/MOM SKIP"),"BASELINE")) -> BASELINE | T29: =IF(I29,0,IF(AND(M29,N29),IF(O29,R29,0),G29)) -> -0.0038 | U29: =G29*Assumptions!$B$6 -> -0.04294 | V29: =T29*Assumptions!$B$6 -> -0.04294 | W29: =V29-U29 -> 0 | X29: =X28*(1+U29) -> 296.3435 | Y29: =MAX(Y28,X29) -> 309.63942 | Z29: =X29/Y29-1 -> -0.04294 | AA29: =AA28*(1+V29) -> 235.50764 | AB29: =MAX(AB28,AA29) -> 246.07406 | AC29: =AA29/AB29-1 -> -0.04294 | AD29: =AA29-X29 -> -60.835862 | AE29: Baseline trade unchanged.
A30: 26 | B30: 43381 | C30: 43384 | D30: GAP DOWN | E30: 7363.47 | F30: 6988.37 | G30: -0.05094 | H30: =SUM(T28:T29) -> 0.00707 | I30: =AND(A30>2,H30<=Assumptions!$B$7) -> FALSE | J30: -0.005469904 | K30: -0.003503599 | L30: -0.0053028853 | M30: =J30>=Assumptions!$B$8 -> FALSE | N30: =AND(K30<>"",K30<=Assumptions!$B$9) -> FALSE | O30: =AND(P30<>"",ABS(L30)<=Assumptions!$B$10) -> FALSE | P30: 43382 | Q30: 7356.97 | R30: -0.0501 | S30: =IF(I30,"DAMAGE SKIP",IF(AND(M30,N30),IF(O30,"TUESDAY RE-ENTRY","GAP/MOM SKIP"),"BASELINE")) -> BASELINE | T30: =IF(I30,0,IF(AND(M30,N30),IF(O30,R30,0),G30)) -> -0.05094 | U30: =G30*Assumptions!$B$6 -> -0.575622 | V30: =T30*Assumptions!$B$6 -> -0.575622 | W30: =V30-U30 -> 0 | X30: =X29*(1+U30) -> 125.76166 | Y30: =MAX(Y29,X30) -> 309.63942 | Z30: =X30/Y30-1 -> -0.59384479 | AA30: =AA29*(1+V30) -> 99.94426 | AB30: =MAX(AB29,AA30) -> 246.07406 | AC30: =AA30/AB30-1 -> -0.59384479 | AD30: =AA30-X30 -> -25.817401 | AE30: Baseline trade unchanged.
A31: 27 | B31: 43388 | C31: 43391 | D31: TSL2 | E31: 7130.37 | F31: 7101.8485 | G31: -0.004 | H31: =SUM(T29:T30) -> -0.05474 | I31: =AND(A31>2,H31<=Assumptions!$B$7) -> TRUE | J31: -0.0031595267 | K31: -0.050911119 | L31: -0.0017209124 | M31: =J31>=Assumptions!$B$8 -> FALSE | N31: =AND(K31<>"",K31<=Assumptions!$B$9) -> TRUE | O31: =AND(P31<>"",ABS(L31)<=Assumptions!$B$10) -> TRUE | P31: 43389 | Q31: 7141.559 | R31: -0.00556 | S31: =IF(I31,"DAMAGE SKIP",IF(AND(M31,N31),IF(O31,"TUESDAY RE-ENTRY","GAP/MOM SKIP"),"BASELINE")) -> DAMAGE SKIP | T31: =IF(I31,0,IF(AND(M31,N31),IF(O31,R31,0),G31)) -> 0 | U31: =G31*Assumptions!$B$6 -> -0.0452 | V31: =T31*Assumptions!$B$6 -> 0 | W31: =V31-U31 -> 0.0452 | X31: =X30*(1+U31) -> 120.07723 | Y31: =MAX(Y30,X31) -> 309.63942 | Z31: =X31/Y31-1 -> -0.61220301 | AA31: =AA30*(1+V31) -> 99.94426 | AB31: =MAX(AB30,AA31) -> 246.07406 | AC31: =AA31/AB31-1 -> -0.59384479 | AD31: =AA31-X31 -> -20.132974 | AE31: Skipped because the previous two rule outcomes totalled at or below the damage threshold.
A32: 28 | B32: 43395 | C32: 43397 | D32: BEPRE | E32: 7143.86 | F32: 7121.069 | G32: -0.00319 | H32: =SUM(T30:T31) -> -0.05094 | I32: =AND(A32>2,H32<=Assumptions!$B$7) -> TRUE | J32: 0.0067772772 | K32: -0.056606462 | L32: -0.012862105 | M32: =J32>=Assumptions!$B$8 -> FALSE | N32: =AND(K32<>"",K32<=Assumptions!$B$9) -> TRUE | O32: =AND(P32<>"",ABS(L32)<=Assumptions!$B$10) -> FALSE | P32: 43396 | Q32: 7010.059 | R32: 0.01583 | S32: =IF(I32,"DAMAGE SKIP",IF(AND(M32,N32),IF(O32,"TUESDAY RE-ENTRY","GAP/MOM SKIP"),"BASELINE")) -> DAMAGE SKIP | T32: =IF(I32,0,IF(AND(M32,N32),IF(O32,R32,0),G32)) -> 0 | U32: =G32*Assumptions!$B$6 -> -0.036047 | V32: =T32*Assumptions!$B$6 -> 0 | W32: =V32-U32 -> 0.036047 | X32: =X31*(1+U32) -> 115.74881 | Y32: =MAX(Y31,X32) -> 309.63942 | Z32: =X32/Y32-1 -> -0.62618192 | AA32: =AA31*(1+V32) -> 99.94426 | AB32: =MAX(AB31,AA32) -> 246.07406 | AC32: =AA32/AB32-1 -> -0.59384479 | AD32: =AA32-X32 -> -15.80455 | AE32: Skipped because the previous two rule outcomes totalled at or below the damage threshold.
A33: 29 | B33: 43402 | C33: 43402 | D33: SL | E33: 6940.259 | F33: 6590.169 | G33: -0.05044 | H33: =SUM(T31:T32) -> 0 | I33: =AND(A33>2,H33<=Assumptions!$B$7) -> FALSE | J33: 0.011307423 | K33: -0.10300521 | L33: -0.022991822 | M33: =J33>=Assumptions!$B$8 -> TRUE | N33: =AND(K33<>"",K33<=Assumptions!$B$9) -> TRUE | O33: =AND(P33<>"",ABS(L33)<=Assumptions!$B$10) -> FALSE | P33: 43403 | Q33: 6684.87 | R33: -0.01416 | S33: =IF(I33,"DAMAGE SKIP",IF(AND(M33,N33),IF(O33,"TUESDAY RE-ENTRY","GAP/MOM SKIP"),"BASELINE")) -> GAP/MOM SKIP | T33: =IF(I33,0,IF(AND(M33,N33),IF(O33,R33,0),G33)) -> 0 | U33: =G33*Assumptions!$B$6 -> -0.569972 | V33: =T33*Assumptions!$B$6 -> 0 | W33: =V33-U33 -> 0.569972 | X33: =X32*(1+U33) -> 49.775229 | Y33: =MAX(Y32,X33) -> 309.63942 | Z33: =X33/Y33-1 -> -0.83924776 | AA33: =AA32*(1+V33) -> 99.94426 | AB33: =MAX(AB32,AA33) -> 246.07406 | AC33: =AA33/AB33-1 -> -0.59384479 | AD33: =AA33-X33 -> 50.169031 | AE33: Monday entry skipped; Tuesday did not normalize within the Friday-based tolerance.
A34: 30 | B34: 43409 | C34: 43413 | D34: TO | E34: 6961.759 | F34: 7030.97 | G34: 0.00994 | H34: =SUM(T32:T33) -> 0 | I34: =AND(A34>2,H34<=Assumptions!$B$7) -> FALSE | J34: 5.7316386e-05 | K34: -0.059735784 | L34: -0.0025854143 | M34: =J34>=Assumptions!$B$8 -> FALSE | N34: =AND(K34<>"",K34<=Assumptions!$B$9) -> TRUE | O34: =AND(P34<>"",ABS(L34)<=Assumptions!$B$10) -> TRUE | P34: 43410 | Q34: 6932.56 | R34: 0.01419 | S34: =IF(I34,"DAMAGE SKIP",IF(AND(M34,N34),IF(O34,"TUESDAY RE-ENTRY","GAP/MOM SKIP"),"BASELINE")) -> BASELINE | T34: =IF(I34,0,IF(AND(M34,N34),IF(O34,R34,0),G34)) -> 0.00994 | U34: =G34*Assumptions!$B$6 -> 0.112322 | V34: =T34*Assumptions!$B$6 -> 0.112322 | W34: =V34-U34 -> 0 | X34: =X33*(1+U34) -> 55.366083 | Y34: =MAX(Y33,X34) -> 309.63942 | Z34: =X34/Y34-1 -> -0.82119175 | AA34: =AA33*(1+V34) -> 111.1702 | AB34: =MAX(AB33,AA34) -> 246.07406 | AC34: =AA34/AB34-1 -> -0.54822463 | AD34: =AA34-X34 -> 55.804117 | AE34: Baseline trade unchanged.
A35: 31 | B35: 43416 | C35: 43419 | D35: TSL1PRE | E35: 6984.77 | F35: 6769.069 | G35: -0.03088 | H35: =SUM(T33:T34) -> 0.00994 | I35: =AND(A35>2,H35<=Assumptions!$B$7) -> FALSE | J35: -0.0065709283 | K35: -0.015997889 | L35: -0.025502121 | M35: =J35>=Assumptions!$B$8 -> FALSE | N35: =AND(K35<>"",K35<=Assumptions!$B$9) -> TRUE | O35: =AND(P35<>"",ABS(L35)<=Assumptions!$B$10) -> FALSE | P35: 43417 | Q35: 6854.77 | R35: -0.0125 | S35: =IF(I35,"DAMAGE SKIP",IF(AND(M35,N35),IF(O35,"TUESDAY RE-ENTRY","GAP/MOM SKIP"),"BASELINE")) -> BASELINE | T35: =IF(I35,0,IF(AND(M35,N35),IF(O35,R35,0),G35)) -> -0.03088 | U35: =G35*Assumptions!$B$6 -> -0.348944 | V35: =T35*Assumptions!$B$6 -> -0.348944 | W35: =V35-U35 -> 0 | X35: =X34*(1+U35) -> 36.04642 | Y35: =MAX(Y34,X35) -> 309.63942 | Z35: =X35/Y35-1 -> -0.88358581 | AA35: =AA34*(1+V35) -> 72.378025 | AB35: =MAX(AB34,AA35) -> 246.07406 | AC35: =AA35/AB35-1 -> -0.70586893 | AD35: =AA35-X35 -> 36.331605 | AE35: Baseline trade unchanged.
A36: 32 | B36: 43423 | C36: 43424 | D36: SLPRE | E36: 6832.46 | F36: 6482.859 | G36: -0.05116 | H36: =SUM(T34:T35) -> -0.02094 | I36: =AND(A36>2,H36<=Assumptions!$B$7) -> TRUE | J36: -0.0053007263 | K36: -0.031801843 | L36: -0.054448681 | M36: =J36>=Assumptions!$B$8 -> FALSE | N36: =AND(K36<>"",K36<=Assumptions!$B$9) -> TRUE | O36: =AND(P36<>"",ABS(L36)<=Assumptions!$B$10) -> FALSE | P36: 43424 | Q36: 6488.569 | R36: -0.00088 | S36: =IF(I36,"DAMAGE SKIP",IF(AND(M36,N36),IF(O36,"TUESDAY RE-ENTRY","GAP/MOM SKIP"),"BASELINE")) -> DAMAGE SKIP | T36: =IF(I36,0,IF(AND(M36,N36),IF(O36,R36,0),G36)) -> 0 | U36: =G36*Assumptions!$B$6 -> -0.578108 | V36: =T36*Assumptions!$B$6 -> 0 | W36: =V36-U36 -> 0.578108 | X36: =X35*(1+U36) -> 15.207696 | Y36: =MAX(Y35,X36) -> 309.63942 | Z36: =X36/Y36-1 -> -0.95088579 | AA36: =AA35*(1+V36) -> 72.378025 | AB36: =MAX(AB35,AA36) -> 246.07406 | AC36: =AA36/AB36-1 -> -0.70586893 | AD36: =AA36-X36 -> 57.170329 | AE36: Skipped because the previous two rule outcomes totalled at or below the damage threshold.
A37: 33 | B37: 43430 | C37: 43430 | D37: CH | E37: 6615.27 | F37: 6684.76 | G37: 0.0105 | H37: =SUM(T35:T36) -> -0.03088 | I37: =AND(A37>2,H37<=Assumptions!$B$7) -> TRUE | J37: 0.014134449 | K37: -0.069123748 | L37: 0.017387594 | M37: =J37>=Assumptions!$B$8 -> TRUE | N37: =AND(K37<>"",K37<=Assumptions!$B$9) -> TRUE | O37: =AND(P37<>"",ABS(L37)<=Assumptions!$B$10) -> FALSE | P37: 43431 | Q37: 6638.47 | R37: 0.00697 | S37: =IF(I37,"DAMAGE SKIP",IF(AND(M37,N37),IF(O37,"TUESDAY RE-ENTRY","GAP/MOM SKIP"),"BASELINE")) -> DAMAGE SKIP | T37: =IF(I37,0,IF(AND(M37,N37),IF(O37,R37,0),G37)) -> 0 | U37: =G37*Assumptions!$B$6 -> 0.11865 | V37: =T37*Assumptions!$B$6 -> 0 | W37: =V37-U37 -> -0.11865 | X37: =X36*(1+U37) -> 17.01209 | Y37: =MAX(Y36,X37) -> 309.63942 | Z37: =X37/Y37-1 -> -0.94505839 | AA37: =AA36*(1+V37) -> 72.378025 | AB37: =MAX(AB36,AA37) -> 246.07406 | AC37: =AA37/AB37-1 -> -0.70586893 | AD37: =AA37-X37 -> 55.365936 | AE37: Skipped because the previous two rule outcomes totalled at or below the damage threshold.
... A40: 36 | B40: 43451 | C40: 43453 | D40: BH | E40: 6570.67 | F40: 6544.3873 | G40: -0.004 | H40: =SUM(T38:T39) -> 0.01346 | I40: =AND(A40>2,H40<=Assumptions!$B$7) -> FALSE | J40: -0.0043941591 | K40: -0.024880407 | L40: -0.014756268 | M40: =J40>=Assumptions!$B$8 -> FALSE | N40: =AND(K40<>"",K40<=Assumptions!$B$9) -> TRUE | O40: =AND(P40<>"",ABS(L40)<=Assumptions!$B$10) -> FALSE | P40: 43452 | Q40: 6497.569 | R40: 0.0072 | S40: =IF(I40,"DAMAGE SKIP",IF(AND(M40,N40),IF(O40,"TUESDAY RE-ENTRY","GAP/MOM SKIP"),"BASELINE")) -> BASELINE | T40: =IF(I40,0,IF(AND(M40,N40),IF(O40,R40,0),G40)) -> -0.004 | U40: =G40*Assumptions!$B$6 -> -0.0452 | V40: =T40*Assumptions!$B$6 -> -0.0452 | W40: =V40-U40 -> 0 | X40: =X39*(1+U40) -> 10.81337 | Y40: =MAX(Y39,X40) -> 309.63942 | Z40: =X40/Y40-1 -> -0.96507754 | AA40: =AA39*(1+V40) -> 79.617505 | AB40: =MAX(AB39,AA40) -> 246.07406 | AC40: =AA40/AB40-1 -> -0.67644901 | AD40: =AA40-X40 -> 68.804134 | AE40: Baseline trade unchanged.
A41: 37 | B41: 43458 | C41: 43460 | D41: CH | E41: 6001.06 | F41: 6272.67 | G41: 0.04526 | H41: =SUM(T39:T40) -> 0.00946 | I41: =AND(A41>2,H41<=Assumptions!$B$7) -> FALSE | J41: -0.007064974 | K41: -0.079718694 | M41: =J41>=Assumptions!$B$8 -> FALSE | N41: =AND(K41<>"",K41<=Assumptions!$B$9) -> TRUE | O41: =AND(P41<>"",ABS(L41)<=Assumptions!$B$10) -> FALSE | S41: =IF(I41,"DAMAGE SKIP",IF(AND(M41,N41),IF(O41,"TUESDAY RE-ENTRY","GAP/MOM SKIP"),"BASELINE")) -> BASELINE | T41: =IF(I41,0,IF(AND(M41,N41),IF(O41,R41,0),G41)) -> 0.04526 | U41: =G41*Assumptions!$B$6 -> 0.511438 | V41: =T41*Assumptions!$B$6 -> 0.511438 | W41: =V41-U41 -> 0 | X41: =X40*(1+U41) -> 16.343739 | Y41: =MAX(Y40,X41) -> 309.63942 | Z41: =X41/Y41-1 -> -0.94721687 | AA41: =AA40*(1+V41) -> 120.33692 | AB41: =MAX(AB40,AA41) -> 246.07406 | AC41: =AA41/AB41-1 -> -0.51097274 | AD41: =AA41-X41 -> 103.99318 | AE41: Baseline trade unchanged.
A42: 38 | B42: 43465 | C42: 43468 | D42: TSL1PRE | E42: 6340.659 | F42: 6221.77 | G42: -0.01875 | H42: =SUM(T40:T41) -> 0.04126 | I42: =AND(A42>2,H42<=Assumptions!$B$7) -> FALSE | J42: 0.011000262 | K42: -0.09060384 | M42: =J42>=Assumptions!$B$8 -> TRUE | N42: =AND(K42<>"",K42<=Assumptions!$B$9) -> TRUE | O42: =AND(P42<>"",ABS(L42)<=Assumptions!$B$10) -> FALSE | S42: =IF(I42,"DAMAGE SKIP",IF(AND(M42,N42),IF(O42,"TUESDAY RE-ENTRY","GAP/MOM SKIP"),"BASELINE")) -> GAP/MOM SKIP | T42: =IF(I42,0,IF(AND(M42,N42),IF(O42,R42,0),G42)) -> 0 | U42: =G42*Assumptions!$B$6 -> -0.211875 | V42: =T42*Assumptions!$B$6 -> 0 | W42: =V42-U42 -> 0.211875 | X42: =X41*(1+U42) -> 12.880909 | Y42: =MAX(Y41,X42) -> 309.63942 | Z42: =X42/Y42-1 -> -0.95840029 | AA42: =AA41*(1+V42) -> 120.33692 | AB42: =MAX(AB41,AA42) -> 246.07406 | AC42: =AA42/AB42-1 -> -0.51097274 | AD42: =AA42-X42 -> 107.45601 | AE42: Monday entry skipped; Tuesday did not normalize within the Friday-based tolerance.
...

Sheet Changed Snapshot
A1: Changed-trade snapshot | B1: Changed-trade snapshot | C1: Changed-trade snapshot | D1: Changed-trade snapshot | E1: Changed-trade snapshot | F1: Changed-trade snapshot | G1: Changed-trade snapshot | H1: Changed-trade snapshot | I1: Changed-trade snapshot | J1: Changed-trade snapshot | K1: Changed-trade snapshot | L1: Changed-trade snapshot
A2: Changed-trade snapshot | B2: Changed-trade snapshot | C2: Changed-trade snapshot | D2: Changed-trade snapshot | E2: Changed-trade snapshot | F2: Changed-trade snapshot | G2: Changed-trade snapshot | H2: Changed-trade snapshot | I2: Changed-trade snapshot | J2: Changed-trade snapshot | K2: Changed-trade snapshot | L2: Changed-trade snapshot
A3: Snapshot membership reflects the stated assumptions. Values remain linked to All Trades. | B3: Snapshot membership reflects the stated assumptions. Values remain linked to All Trades. | C3: Snapshot membership reflects the stated assumptions. Values remain linked to All Trades. | D3: Snapshot membership reflects the stated assumptions. Values remain linked to All Trades. | E3: Snapshot membership reflects the stated assumptions. Values remain linked to All Trades. | F3: Snapshot membership reflects the stated assumptions. Values remain linked to All Trades. | G3: Snapshot membership reflects the stated assumptions. Values remain linked to All Trades. | H3: Snapshot membership reflects the stated assumptions. Values remain linked to All Trades. | I3: Snapshot membership reflects the stated assumptions. Values remain linked to All Trades. | J3: Snapshot membership reflects the stated assumptions. Values remain linked to All Trades. | K3: Snapshot membership reflects the stated assumptions. Values remain linked to All Trades. | L3: Snapshot membership reflects the stated assumptions. Values remain linked to All Trades.
A4: Trade # | B4: Open date | C4: Close date | D4: Exit reason | E4: Baseline raw | F4: Rule action | G4: Rule raw | H4: 11.3x difference | I4: Cash-open gap | J4: Momentum 20d | K4: Tuesday vs Friday | L4: Notes
A5: ='All Trades'!A8 -> 4 | B5: ='All Trades'!B8 -> 43227 | C5: ='All Trades'!C8 -> 43231 | D5: ='All Trades'!D8 -> TO | E5: ='All Trades'!G8 -> 0.02286 | F5: ='All Trades'!S8 -> DAMAGE SKIP | G5: ='All Trades'!T8 -> 0 | H5: ='All Trades'!W8 -> -0.258318 | I5: ='All Trades'!J8 -> 0.0044332821 | J5: ='All Trades'!K8 -> 0 | K5: ='All Trades'!L8 -> 0.0056134009 | L5: ='All Trades'!AE8 -> Skipped because the previous two rule outcomes totalled at or below the damage threshold.
